Workbook
Name cnhlist: '[1]CNH Prices'!$C$3:$E$47
Name OLE_LINK1: Template!#REF!
Name 首頁日期: Template!#REF!

Sheet Template
C1: 全球市場總覽 | P1: ="Fixed income market analysis "&TEXT(TODAY(),"dd-mmm-yyyy") -> Fixed income market analysis 07-Aug-2026 | S1: 重點發行人市場表現 | AJ1: 美國投資等級債券初級市場 | BB1: 美國投資等級債券初級市場 | BT1: Weely Bond Flow | CK1: 焦點新聞 | DB1: 焦點新聞 | DR1: 焦點新聞 | EG1: 焦點_稀土貿易戰 | EX1: 焦點_私募信貸的隱憂
A5: Fixed Income Markets Frontier | C5: 債市回顧及展望 | Q5: Fixed Income Markets Frontier | S5: 產業 | T5: 公司名稱 | U5: 中文名稱 | V5: 股價/匯價 | W5: 1W %△ | X5: CDS | Y5: 1W △ | Z5: YTD △ | AA5: S&P | AB5: Moody's | AC5: Fitch | AH5: Fixed Income Markets Frontier | AJ5: 11/11~11/17市場回顧 | AX5: =TODAY() -> 46241 | AZ5: Fixed Income Markets Frontier | BB5: Ticker | BC5: 發行人 | BD5: ISIN | BE5: 定價日 | BF5: 發行量(MM) | BH5: 天期 | BI5: 票息 | BJ5: 償債順位 | BK5: 殖利率 | BL5: S&P | BM5: Moody's | BN5: Fitch | BO5: 認購倍數 | BR5: Fixed Income Markets Frontier | BT5: 投資等級債券交易量 Top 20 | CI5: Fixed Income Markets Frontier | CK5: APA / REPSEP | CR5: 迪士尼 (DIS) | CZ5: Fixed Income Markets Frontier | DB5: 優步 (UBER) | DI5: AppLovin (APP) | DP5: Fixed Income Markets Frontier | EE5: Fixed Income Markets Frontier | EG5: 中國稀土出口管制措施 | EN5: 全球稀土出口與精煉比例 | EV5: Fixed Income Markets Frontier | EX5: 近期私募信貸事件
C7: 上週美債10y利率維持10bps之內震盪，全週利率微漲2bps，curve steepen。美國政府結束關門，投資者等待勞動力市場與通膨數據更新。上半週債券交易員大量買入壓注10y美債收益率跌破4%的期權，因為即將公布的一系列數據可能重塑市場對美國經濟前景的預期。上週以來加密貨幣大跌，比特幣抹去今年以來所有漲幅，標普500較全球股指溢價逾50%，上週以來股市的selloff顯示出投機情緒正在退場；目前市場對風險擔憂的情緒略有升溫，部分原因仍來自脆弱的信用相關數據以及偏緊的資金。根據惠譽評級的數據，美國10月份次級車貸違約率創新高，而緊接大空頭Michael Burry質疑科技巨頭通過延長計算設備折舊年限可能在帳面上虛增盈利增速後，新債王Gundlach將矛頭直指私人信貸市場，認為風險正源於對私營企業的危險貸款及對人工智能的過度期待，並可能將全球市場推向新一輪崩盤。資金部分，近幾週一系列短期利率居高不下，SOFR甚至出現自2020年3月疫情高峰以來非加息週期中的單日最大波動，造成市場緊縮的主因是國庫券發行增加，吸走了短期市場現金，令銀行體系流動性減少，以回購為基礎的基準利率進一步高於美聯儲支付給銀行準備金的利率(IORB)水平，而美聯儲的常設回購機制(SRF)近幾週亦被頻繁使用。在風險情緒降溫的上週，多位Fed官員釋出鷹派訊號，期貨市場目前預期美國12月降息1碼的機率僅剩42.9%。 其它市場部分，日圓兌美元匯率跌至155，創今年2月以來新低，預計將促使東京官員行使口頭干預以遏制匯率下滑；美國關稅打擊日本出口，拖累日本Q3 GDP季減年率1.8%，創下六季以來首次萎縮紀錄；澳州10月就業人數增加42200人，高於預估的20000人，顯示就業市場依舊有韌性。 展望本週，美國即將公布一系列數據，重要數據公布時間如下，11/20公布9月非農就業報告、21日為9月實際薪資數據、26日將發布Q3 GDP修正值，當天10月個人所得支出以及PCE指數也將出爐；12/4將公布10月國際貿易報告，5日公布11月就業報告，10日則預定公布11月CPI，緊接著就是今年最後一次的FOMC會議。Fund flow部分，美股連續第9週淨流入($6.4bn)、IG bonds連續29週淨流入($10.9bn)；技術分析部分，雖10y美債利率日線於上週打破向下格局，但週月線仍延續下行趨勢，30y利率目前則來到4.74~4.76%壓力區，向上力道應不至於持續。 | S7: 金融 | T7: =VLOOKUP($AD7,'市場監控 '!$E$7:$W$194,6,FALSE) -> #NAME? | U7: =VLOOKUP($AD7,'市場監控 '!$E$7:$W$194,7,FALSE) -> #NAME? | V7: =VLOOKUP($AD7,'市場監控 '!$E$7:$W$194,8,FALSE) -> - | W7: =VLOOKUP($AD7,'市場監控 '!$E$7:$W$194,10,FALSE) -> - | X7: =VLOOKUP($AD7,'市場監控 '!$E$7:$W$194,12,FALSE) -> - | Y7: =VLOOKUP($AD7,'市場監控 '!$E$7:$W$194,14,FALSE) -> - | Z7: =VLOOKUP($AD7,'市場監控 '!$E$7:$W$194,15,FALSE) -> - | AA7: =VLOOKUP($AD7,'市場監控 '!$E$7:$W$194,17,FALSE) -> #NAME? | AB7: =VLOOKUP($AD7,'市場監控 '!$E$7:$W$194,18,FALSE) -> #NAME? | AC7: =VLOOKUP($AD7,'市場監控 '!$E$7:$W$194,19,FALSE) -> #NAME? | AD7: ANZ AU Equity | AE7: 中國銀行股份有限公司 | AJ7: 上週IG信用利差整體走窄，全週+1~+5bps，US IG widen 2bp，US HY widen 17bps。 S&P將UPS展望調整為負面，UPS信用利差widen 2bps。Moody’s 將 AppLovin 的高級無擔保評級上調至 Baa3，展望為正向。 11/12：IG closed +1/2bps。TMT underperformed，不同發行人漲跌各異(PARA -8, VZ +1, GOOGL +2, META +3, ORCL +13)，ORCL而後有short covering flow 。 初級市場 11/12：4個發行人定價$4.4bn IG bonds，NIC 1bps，認購倍數4x。Host Hotel發行$400mio WNG 3y券，獲得10x的認購峰值。 11/13：6個發行人定價$3.6bn IG bonds，NIC 4bps，認購倍數2.5x。DXC Technology在4年後發行5y券，IPT提供了大約50bps的NIC，由於股市不佳，order book僅$650mio，guidance unchanged。 11/17：10個發行人定價$26.3bn IG bonds，NIC 2bps，認購倍數3.6x。Amazon為近期發行量最大的發行人，定價$15bn債券。由於股市selloff，order book attrition攀高至40%，幾乎是YTD平均21%的兩倍。 | BB7: =VLOOKUP($BD7,NI!$B$5:$AL$2030,6,FALSE) -> #NAME? | BC7: =VLOOKUP($BD7,NI!$B$37:$AL$2030,2,FALSE) -> #NAME? | BD7: =NI!$B65 -> #NAME? | BE7: =VLOOKUP($BD7,NI!$B$5:$AL$2030,11,FALSE) -> #NAME? | BF7: =VLOOKUP($BD7,NI!$B$5:$AL$2030,12,FALSE)/1000000 -> #NAME? | BH7: =IF(ISNUMBER(VLOOKUP($BD7,NI!$B$5:$AL$2030,13,FALSE)),VLOOKUP($BD7,NI!$B$5:$AL$2030,13,FALSE),"-") -> - | BI7: =VLOOKUP($BD7,NI!$B$5:$AL$2030,4,FALSE) -> #NAME? | BJ7: =VLOOKUP($BD7,NI!$B$5:$AL$2030,3,FALSE) -> #NAME? | BK7: =VLOOKUP($BD7,NI!$B$5:$AL$2030,4,FALSE) -> #NAME? | BL7: =IF(LEFT(VLOOKUP($BD7,NI!$B$5:$AL$2030,31,FALSE),1)="#","-",VLOOKUP($BD7,NI!$B$5:$AL$2030,31,FALSE)) -> #NAME? | BM7: =IF(LEFT(VLOOKUP($BD7,NI!$B$5:$AL$2030,32,FALSE),1)="#","-",VLOOKUP($BD7,NI!$B$5:$AL$2030,32,FALSE)) -> #NAME? | BN7: =IF(LEFT(VLOOKUP($BD7,NI!$B$5:$AL$2030,33,FALSE),1)="#","-",VLOOKUP($BD7,NI!$B$5:$AL$2030,33,FALSE)) -> #NAME? | BO7: =VLOOKUP($BD7,NI!$B$5:$AL$2030,22,FALSE) -> #NAME? | BT7: Ticker | BU7: 發行人 | BV7: ISIN | BW7: 票面利率 | BX7: 天期 (y) | BZ7: 償債順位 | CA7: 目前殖利率 | CB7: 筆數 | CC7: 總量 (M) | CD7: S&P | CE7: Moody's | CF7: Fitch | CK7: Repsol 正在考慮將其上游業務與 Apache（以及其他潛在合併夥伴）進行反向合併，這可能為其提供更快速的途徑成為上市公司。目前的細節對我們來說是信用正面的，因為這將意味著更大的規模和更高的多元化，且槓桿率不會有顯著變化。假設上述條件成立，該合併後的實體信用利差可能會tighten 15~20bps ，但需要注意的是，Repsol 仍處於「考慮選項」的階段。APA 應該表現優於市場，因為一些人可能將此視為向其他潛在買家的開放機會。 11/13消息公布後，APA信用利差tighten 7bps，REPSEP信用利差tighten 3bps。 | CR7: 迪士尼獲利優於分析師估計，不過旗下有線電視與傳統電視業務持續萎縮，抵銷串流與主題樂園的亮眼表現，使股價在美股盤前一度下跌逾 5%。回購金額從 $3.5bn提高到$7bn，根據他們提供的指引，這應該會需要發行債券。迪士尼目前有約 $7bn的短期債務，其中大部分可能會尋求再融資。 營收：$22.5bn（低於預期 $22.7bn~22.8bn） EPS：$1.11（優於預期 $1.05~$1.07） 營運利益：$352mio（年增 39%） 11/13財報公布後，DIS股價下跌7.8%。 | DB7: 營收與獲利皆大幅優於預期，受惠於稅務利益與平台用戶成長。Q3行程數創歷史新高，毛利率提升。儘管Q4指引略低於市場預期，管理層強調AI與多元商業模式為未來成長動能。 營收：$13.47bn（年增 20%，優於預期） EPS：$3.11（含 $4.9bn 稅務利益） 淨利：$6.6bn 營業利潤率：8.1%（Adjusted EBITDA $2.3bn，年增 33%） 行程數：3.5bn（年增 22%） 自由現金流：$2.2bn 平台用戶：189m（年增 17%） 11/4消息公布後，UBER股價下跌5.1%。 | DI7: 季度表現穩健，槓桿率現在低於1倍。過去12個月的EBITDA約為$4bn，相較於$3.5bn 的債務，槓桿率為0.9倍，淨槓桿率為0.5倍。第三季FCF達到$1.05bn，過去12個月的FCF為33.4億美元。 營收：$1.41bn（年增 68%，預期 $1.34bn） EPS：$2.45（年增 96%，預期 $2.38） 淨利：$836mio（年增 92%） Adjusted EBITDA：$1.16bn（年增 79%，EBITDA margin 82%） 自由現金流：$1.05bn（年增 92%） 現金與等值資產：$1.7bn 股數：339M（Q3末） 回購：Q3回購1.3M股，總額 $571M；授權擴大 $3.2B，剩餘 $3.3B 11/6消息公布後，APP股價持平。 | EG7: 中國商務部在10/9發布「2025 年第 61 號」公告，自2025年12月起，擴大稀土管制： - 新增五種稀土元素及多項提煉設備。 - 凡產品含有超過 0.1% 中國稀土成分，或使用中國稀土技術者，出口前須申請許可。 - 軍事用途稀土材料全面禁止出口，包括導彈、戰機、潛艦、雷射、測距儀等關鍵零件。 美國對稀土出口管制的回應： - 宣布自 11/1 起（或更早視情況）對中輸美商品加徵額外 100% 關稅，並祭出「關鍵軟體」出口管制。 - 美國與 G7國家（包括歐盟、日本、韓國等）展開協調行動，尋求建立替代稀土供應鏈。 產業影響： - 軍功產業受創：稀土磁鐵是精密導引、隱形技術與高功率馬達的核心元件。 - 半導體與AI產業供應鏈中斷：晶片電容器使用「超純鏑」製造，全球供應幾乎全來自中國無錫市一家精煉廠。 - 電動車與能源產業成本上升：電動車馬達與風力發電機使用大量稀土磁鐵，傳統燃油車也使用稀土磁鐵於座椅、方向盤、煞車系統等。 本次管制清單並未涵蓋全球用量最大的輕稀土「釹」和「鐠」，因為，若全面禁止，將讓全球電動車和風點產業瞬間停擺，也損害中國自身的下游客戶。選擇性的管制重稀土，則達到精準打擊並製造威攝的多重戰略目的。 | EN7: 國家/地區 | EO7: 開採比例 (%) | EP7: 精煉比例 (%) | EQ7: 出口比例 (%) | ER7: 補充說明 | EX7: 事件 | EZ7: 時間 | FA7: 內容 | FD7: 結果 | FH7: 影響
T8: =VLOOKUP($AD8,'市場監控 '!$E$7:$W$194,6,FALSE) -> #NAME? | U8: =VLOOKUP($AD8,'市場監控 '!$E$7:$W$194,7,FALSE) -> #NAME? | V8: =VLOOKUP($AD8,'市場監控 '!$E$7:$W$194,8,FALSE) -> - | W8: =VLOOKUP($AD8,'市場監控 '!$E$7:$W$194,10,FALSE) -> - | X8: =VLOOKUP($AD8,'市場監控 '!$E$7:$W$194,12,FALSE) -> - | Y8: =VLOOKUP($AD8,'市場監控 '!$E$7:$W$194,14,FALSE) -> - | Z8: =VLOOKUP($AD8,'市場監控 '!$E$7:$W$194,15,FALSE) -> - | AA8: =VLOOKUP($AD8,'市場監控 '!$E$7:$W$194,17,FALSE) -> #NAME? | AB8: =VLOOKUP($AD8,'市場監控 '!$E$7:$W$194,18,FALSE) -> #NAME? | AC8: =VLOOKUP($AD8,'市場監控 '!$E$7:$W$194,19,FALSE) -> #NAME? | AD8: CBA AU Equity | AE8: 中國工商銀行股份有限公司 | BB8: =VLOOKUP($BD8,NI!$B$5:$AL$2030,6,FALSE) -> #NAME? | BC8: =VLOOKUP($BD8,NI!$B$37:$AL$2030,2,FALSE) -> #NAME? | BD8: =NI!$B66 -> #NAME? | BE8: =VLOOKUP($BD8,NI!$B$5:$AL$2030,11,FALSE) -> #NAME? | BF8: =VLOOKUP($BD8,NI!$B$5:$AL$2030,12,FALSE)/1000000 -> #NAME? | BH8: =IF(ISNUMBER(VLOOKUP($BD8,NI!$B$5:$AL$2030,13,FALSE)),VLOOKUP($BD8,NI!$B$5:$AL$2030,13,FALSE),"-") -> - | BI8: =VLOOKUP($BD8,NI!$B$5:$AL$2030,4,FALSE) -> #NAME? | BJ8: =VLOOKUP($BD8,NI!$B$5:$AL$2030,3,FALSE) -> #NAME? | BK8: =VLOOKUP($BD8,NI!$B$5:$AL$2030,4,FALSE) -> #NAME? | BL8: =IF(LEFT(VLOOKUP($BD8,NI!$B$5:$AL$2030,31,FALSE),1)="#","-",VLOOKUP($BD8,NI!$B$5:$AL$2030,31,FALSE)) -> #NAME? | BM8: =IF(LEFT(VLOOKUP($BD8,NI!$B$5:$AL$2030,32,FALSE),1)="#","-",VLOOKUP($BD8,NI!$B$5:$AL$2030,32,FALSE)) -> #NAME? | BN8: =IF(LEFT(VLOOKUP($BD8,NI!$B$5:$AL$2030,33,FALSE),1)="#","-",VLOOKUP($BD8,NI!$B$5:$AL$2030,33,FALSE)) -> #NAME? | BO8: =VLOOKUP($BD8,NI!$B$5:$AL$2030,22,FALSE) -> #NAME? | BT8: =VLOOKUP($BV8,TACT!$A$3:$AH$100,2,FALSE) -> #NAME? | BU8: =VLOOKUP($BV8,TACT!$A$3:$AH$100,3,FALSE) -> #NAME? | BV8: =TACT!$A3 -> #NAME? | BW8: =VLOOKUP($BV8,TACT!$A$3:$AH$100,11,FALSE) -> #NAME? | BX8: =VLOOKUP($BV8,TACT!$A$3:$AH$100,5,FALSE) -> #NAME? | BZ8: =VLOOKUP($BV8,TACT!$A$3:$AH$100,4,FALSE) -> #NAME? | CA8: =VLOOKUP($BV8,TACT!$A$3:$AH$100,21,FALSE) -> #NAME? | CB8: =VLOOKUP($BV8,TACT!$A$3:$AH$100,32,FALSE) -> #NAME? | CC8: =VLOOKUP($BV8,TACT!$A$3:$AH$100,33,FALSE) -> #NAME? | CD8: =IF(LEFT(VLOOKUP($BV8,TACT!$A$3:$AH$100,6,FALSE),1)="#","-",VLOOKUP($BV8,TACT!$A$3:$AH$100,6,FALSE)) -> #NAME? | CE8: =IF(LEFT(VLOOKUP($BV8,TACT!$A$3:$AH$100,7,FALSE),1)="#","-",VLOOKUP($BV8,TACT!$A$3:$AH$100,7,FALSE)) -> #NAME? | CF8: =IF(LEFT(VLOOKUP($BV8,TACT!$A$3:$AH$100,8,FALSE),1)="#","-",VLOOKUP($BV8,TACT!$A$3:$AH$100,8,FALSE)) -> #NAME?
T9: =VLOOKUP($AD9,'市場監控 '!$E$7:$W$194,6,FALSE) -> #NAME? | U9: =VLOOKUP($AD9,'市場監控 '!$E$7:$W$194,7,FALSE) -> #NAME? | V9: =VLOOKUP($AD9,'市場監控 '!$E$7:$W$194,8,FALSE) -> - | W9: =VLOOKUP($AD9,'市場監控 '!$E$7:$W$194,10,FALSE) -> - | X9: =VLOOKUP($AD9,'市場監控 '!$E$7:$W$194,12,FALSE) -> - | Y9: =VLOOKUP($AD9,'市場監控 '!$E$7:$W$194,14,FALSE) -> - | Z9: =VLOOKUP($AD9,'市場監控 '!$E$7:$W$194,15,FALSE) -> - | AA9: =VLOOKUP($AD9,'市場監控 '!$E$7:$W$194,17,FALSE) -> #NAME? | AB9: =VLOOKUP($AD9,'市場監控 '!$E$7:$W$194,18,FALSE) -> #NAME? | AC9: =VLOOKUP($AD9,'市場監控 '!$E$7:$W$194,19,FALSE) -> #NAME? | AD9: NAB AU Equity | AE9: 中國建設銀行股份有限公司 | BB9: =VLOOKUP($BD9,NI!$B$5:$AL$2030,6,FALSE) -> #NAME? | BC9: =VLOOKUP($BD9,NI!$B$37:$AL$2030,2,FALSE) -> #NAME? | BD9: =NI!$B67 -> #NAME? | BE9: =VLOOKUP($BD9,NI!$B$5:$AL$2030,11,FALSE) -> #NAME? | BF9: =VLOOKUP($BD9,NI!$B$5:$AL$2030,12,FALSE)/1000000 -> #NAME? | BH9: =IF(ISNUMBER(VLOOKUP($BD9,NI!$B$5:$AL$2030,13,FALSE)),VLOOKUP($BD9,NI!$B$5:$AL$2030,13,FALSE),"-") -> - | BI9: =VLOOKUP($BD9,NI!$B$5:$AL$2030,4,FALSE) -> #NAME? | BJ9: =VLOOKUP($BD9,NI!$B$5:$AL$2030,3,FALSE) -> #NAME? | BK9: =VLOOKUP($BD9,NI!$B$5:$AL$2030,4,FALSE) -> #NAME? | BL9: =IF(LEFT(VLOOKUP($BD9,NI!$B$5:$AL$2030,31,FALSE),1)="#","-",VLOOKUP($BD9,NI!$B$5:$AL$2030,31,FALSE)) -> #NAME? | BM9: =IF(LEFT(VLOOKUP($BD9,NI!$B$5:$AL$2030,32,FALSE),1)="#","-",VLOOKUP($BD9,NI!$B$5:$AL$2030,32,FALSE)) -> #NAME? | BN9: =IF(LEFT(VLOOKUP($BD9,NI!$B$5:$AL$2030,33,FALSE),1)="#","-",VLOOKUP($BD9,NI!$B$5:$AL$2030,33,FALSE)) -> #NAME? | BO9: =VLOOKUP($BD9,NI!$B$5:$AL$2030,22,FALSE) -> #NAME? | BT9: =VLOOKUP($BV9,TACT!$A$3:$AH$100,2,FALSE) -> #NAME? | BU9: =VLOOKUP($BV9,TACT!$A$3:$AH$100,3,FALSE) -> #NAME? | BV9: =TACT!$A4 -> #NAME? | BW9: =VLOOKUP($BV9,TACT!$A$3:$AH$100,11,FALSE) -> #NAME? | BX9: =VLOOKUP($BV9,TACT!$A$3:$AH$100,5,FALSE) -> #NAME? | BZ9: =VLOOKUP($BV9,TACT!$A$3:$AH$100,4,FALSE) -> #NAME? | CA9: =VLOOKUP($BV9,TACT!$A$3:$AH$100,21,FALSE) -> #NAME? | CB9: =VLOOKUP($BV9,TACT!$A$3:$AH$100,32,FALSE) -> #NAME? | CC9: =VLOOKUP($BV9,TACT!$A$3:$AH$100,33,FALSE) -> #NAME? | CD9: =IF(LEFT(VLOOKUP($BV9,TACT!$A$3:$AH$100,6,FALSE),1)="#","-",VLOOKUP($BV9,TACT!$A$3:$AH$100,6,FALSE)) -> #NAME? | CE9: =IF(LEFT(VLOOKUP($BV9,TACT!$A$3:$AH$100,7,FALSE),1)="#","-",VLOOKUP($BV9,TACT!$A$3:$AH$100,7,FALSE)) -> #NAME? | CF9: =IF(LEFT(VLOOKUP($BV9,TACT!$A$3:$AH$100,8,FALSE),1)="#","-",VLOOKUP($BV9,TACT!$A$3:$AH$100,8,FALSE)) -> #NAME? | EN9: 中國 | EO9: 60 | EP9: 90 | EQ9: 60 | ER9: 全球唯一能提供全部17種稀土金屬的國家 | EX9: Tricolor Holdings 與 First Brands Group 破產 | EZ9: 2025年9月 | FA9: 1. Tricolor：二手車貸款機構，疑涉欺詐，導致摩根大通損失1.7億美元。 2. First Brands：汽車零件供應商，依賴私募與對沖基金融資，部分資產重複抵押。約有100~500億美元債務。 | FD9: 1. 多家銀行（如摩根大通、Fifth Third Bancorp）曝險。 2. 私募信貸市場震盪，Blue Owl Capital股價重挫。 | FH9: 1. 引發「蟑螂理論」擔憂：一宗壞帳可能代表更多潛在風險。 2. 信貸品質與放貸審查標準遭質疑。 3. 私募信貸與高收益債市場利差擴大，投資人風險意識升高。
T10: =VLOOKUP($AD10,'市場監控 '!$E$7:$W$194,6,FALSE) -> #NAME? | U10: =VLOOKUP($AD10,'市場監控 '!$E$7:$W$194,7,FALSE) -> #NAME? | V10: =VLOOKUP($AD10,'市場監控 '!$E$7:$W$194,8,FALSE) -> - | W10: =VLOOKUP($AD10,'市場監控 '!$E$7:$W$194,10,FALSE) -> - | X10: =VLOOKUP($AD10,'市場監控 '!$E$7:$W$194,12,FALSE) -> - | Y10: =VLOOKUP($AD10,'市場監控 '!$E$7:$W$194,14,FALSE) -> - | Z10: =VLOOKUP($AD10,'市場監控 '!$E$7:$W$194,15,FALSE) -> - | AA10: =VLOOKUP($AD10,'市場監控 '!$E$7:$W$194,17,FALSE) -> #NAME? | AB10: =VLOOKUP($AD10,'市場監控 '!$E$7:$W$194,18,FALSE) -> #NAME? | AC10: =VLOOKUP($AD10,'市場監控 '!$E$7:$W$194,19,FALSE) -> #NAME? | AD10: WBC AU Equity | AE10: 交通銀行股份有限公司 | BB10: =VLOOKUP($BD10,NI!$B$5:$AL$2030,6,FALSE) -> #NAME? | BC10: =VLOOKUP($BD10,NI!$B$37:$AL$2030,2,FALSE) -> #NAME? | BD10: =NI!$B68 -> #NAME? | BE10: =VLOOKUP($BD10,NI!$B$5:$AL$2030,11,FALSE) -> #NAME? | BF10: =VLOOKUP($BD10,NI!$B$5:$AL$2030,12,FALSE)/1000000 -> #NAME? | BH10: =IF(ISNUMBER(VLOOKUP($BD10,NI!$B$5:$AL$2030,13,FALSE)),VLOOKUP($BD10,NI!$B$5:$AL$2030,13,FALSE),"-") -> - | BI10: =VLOOKUP($BD10,NI!$B$5:$AL$2030,4,FALSE) -> #NAME? | BJ10: =VLOOKUP($BD10,NI!$B$5:$AL$2030,3,FALSE) -> #NAME? | BK10: =VLOOKUP($BD10,NI!$B$5:$AL$2030,4,FALSE) -> #NAME? | BL10: =IF(LEFT(VLOOKUP($BD10,NI!$B$5:$AL$2030,31,FALSE),1)="#","-",VLOOKUP($BD10,NI!$B$5:$AL$2030,31,FALSE)) -> #NAME? | BM10: =IF(LEFT(VLOOKUP($BD10,NI!$B$5:$AL$2030,32,FALSE),1)="#","-",VLOOKUP($BD10,NI!$B$5:$AL$2030,32,FALSE)) -> #NAME? | BN10: =IF(LEFT(VLOOKUP($BD10,NI!$B$5:$AL$2030,33,FALSE),1)="#","-",VLOOKUP($BD10,NI!$B$5:$AL$2030,33,FALSE)) -> #NAME? | BO10: =VLOOKUP($BD10,NI!$B$5:$AL$2030,22,FALSE) -> #NAME? | BT10: =VLOOKUP($BV10,TACT!$A$3:$AH$100,2,FALSE) -> #NAME? | BU10: =VLOOKUP($BV10,TACT!$A$3:$AH$100,3,FALSE) -> #NAME? | BV10: =TACT!$A5 -> #NAME? | BW10: =VLOOKUP($BV10,TACT!$A$3:$AH$100,11,FALSE) -> #NAME? | BX10: =VLOOKUP($BV10,TACT!$A$3:$AH$100,5,FALSE) -> #NAME? | BZ10: =VLOOKUP($BV10,TACT!$A$3:$AH$100,4,FALSE) -> #NAME? | CA10: =VLOOKUP($BV10,TACT!$A$3:$AH$100,21,FALSE) -> #NAME? | CB10: =VLOOKUP($BV10,TACT!$A$3:$AH$100,32,FALSE) -> #NAME? | CC10: =VLOOKUP($BV10,TACT!$A$3:$AH$100,33,FALSE) -> #NAME? | CD10: =IF(LEFT(VLOOKUP($BV10,TACT!$A$3:$AH$100,6,FALSE),1)="#","-",VLOOKUP($BV10,TACT!$A$3:$AH$100,6,FALSE)) -> #NAME? | CE10: =IF(LEFT(VLOOKUP($BV10,TACT!$A$3:$AH$100,7,FALSE),1)="#","-",VLOOKUP($BV10,TACT!$A$3:$AH$100,7,FALSE)) -> #NAME? | CF10: =IF(LEFT(VLOOKUP($BV10,TACT!$A$3:$AH$100,8,FALSE),1)="#","-",VLOOKUP($BV10,TACT!$A$3:$AH$100,8,FALSE)) -> #NAME?
T11: =VLOOKUP($AD11,'市場監控 '!$E$7:$W$194,6,FALSE) -> #NAME? | U11: =VLOOKUP($AD11,'市場監控 '!$E$7:$W$194,7,FALSE) -> #NAME? | V11: =VLOOKUP($AD11,'市場監控 '!$E$7:$W$194,8,FALSE) -> - | W11: =VLOOKUP($AD11,'市場監控 '!$E$7:$W$194,10,FALSE) -> - | X11: =VLOOKUP($AD11,'市場監控 '!$E$7:$W$194,12,FALSE) -> - | Y11: =VLOOKUP($AD11,'市場監控 '!$E$7:$W$194,14,FALSE) -> - | Z11: =VLOOKUP($AD11,'市場監控 '!$E$7:$W$194,15,FALSE) -> - | AA11: =VLOOKUP($AD11,'市場監控 '!$E$7:$W$194,17,FALSE) -> #NAME? | AB11: =VLOOKUP($AD11,'市場監控 '!$E$7:$W$194,18,FALSE) -> #NAME? | AC11: =VLOOKUP($AD11,'市場監控 '!$E$7:$W$194,19,FALSE) -> #NAME? | AD11: BNP FP Equity | AE11: 中國農業銀行股份有限公司 | BB11: =VLOOKUP($BD11,NI!$B$5:$AL$2030,6,FALSE) -> #NAME? | BC11: =VLOOKUP($BD11,NI!$B$37:$AL$2030,2,FALSE) -> #NAME? | BD11: =NI!$B69 -> #NAME? | BE11: =VLOOKUP($BD11,NI!$B$5:$AL$2030,11,FALSE) -> #NAME? | BF11: =VLOOKUP($BD11,NI!$B$5:$AL$2030,12,FALSE)/1000000 -> #NAME? | BH11: =IF(ISNUMBER(VLOOKUP($BD11,NI!$B$5:$AL$2030,13,FALSE)),VLOOKUP($BD11,NI!$B$5:$AL$2030,13,FALSE),"-") -> - | BI11: =VLOOKUP($BD11,NI!$B$5:$AL$2030,4,FALSE) -> #NAME? | BJ11: =VLOOKUP($BD11,NI!$B$5:$AL$2030,3,FALSE) -> #NAME? | BK11: =VLOOKUP($BD11,NI!$B$5:$AL$2030,4,FALSE) -> #NAME? | BL11: =IF(LEFT(VLOOKUP($BD11,NI!$B$5:$AL$2030,31,FALSE),1)="#","-",VLOOKUP($BD11,NI!$B$5:$AL$2030,31,FALSE)) -> #NAME? | BM11: =IF(LEFT(VLOOKUP($BD11,NI!$B$5:$AL$2030,32,FALSE),1)="#","-",VLOOKUP($BD11,NI!$B$5:$AL$2030,32,FALSE)) -> #NAME? | BN11: =IF(LEFT(VLOOKUP($BD11,NI!$B$5:$AL$2030,33,FALSE),1)="#","-",VLOOKUP($BD11,NI!$B$5:$AL$2030,33,FALSE)) -> #NAME? | BO11: =VLOOKUP($BD11,NI!$B$5:$AL$2030,22,FALSE) -> #NAME? | BT11: =VLOOKUP($BV11,TACT!$A$3:$AH$100,2,FALSE) -> #NAME? | BU11: =VLOOKUP($BV11,TACT!$A$3:$AH$100,3,FALSE) -> #NAME? | BV11: =TACT!$A6 -> #NAME? | BW11: =VLOOKUP($BV11,TACT!$A$3:$AH$100,11,FALSE) -> #NAME? | BX11: =VLOOKUP($BV11,TACT!$A$3:$AH$100,5,FALSE) -> #NAME? | BZ11: =VLOOKUP($BV11,TACT!$A$3:$AH$100,4,FALSE) -> #NAME? | CA11: =VLOOKUP($BV11,TACT!$A$3:$AH$100,21,FALSE) -> #NAME? | CB11: =VLOOKUP($BV11,TACT!$A$3:$AH$100,32,FALSE) -> #NAME? | CC11: =VLOOKUP($BV11,TACT!$A$3:$AH$100,33,FALSE) -> #NAME? | CD11: =IF(LEFT(VLOOKUP($BV11,TACT!$A$3:$AH$100,6,FALSE),1)="#","-",VLOOKUP($BV11,TACT!$A$3:$AH$100,6,FALSE)) -> #NAME? | CE11: =IF(LEFT(VLOOKUP($BV11,TACT!$A$3:$AH$100,7,FALSE),1)="#","-",VLOOKUP($BV11,TACT!$A$3:$AH$100,7,FALSE)) -> #NAME? | CF11: =IF(LEFT(VLOOKUP($BV11,TACT!$A$3:$AH$100,8,FALSE),1)="#","-",VLOOKUP($BV11,TACT!$A$3:$AH$100,8,FALSE)) -> #NAME?
T12: =VLOOKUP($AD12,'市場監控 '!$E$7:$W$194,6,FALSE) -> #NAME? | U12: =VLOOKUP($AD12,'市場監控 '!$E$7:$W$194,7,FALSE) -> #NAME? | V12: =VLOOKUP($AD12,'市場監控 '!$E$7:$W$194,8,FALSE) -> - | W12: =VLOOKUP($AD12,'市場監控 '!$E$7:$W$194,10,FALSE) -> - | X12: =VLOOKUP($AD12,'市場監控 '!$E$7:$W$194,12,FALSE) -> - | Y12: =VLOOKUP($AD12,'市場監控 '!$E$7:$W$194,14,FALSE) -> - | Z12: =VLOOKUP($AD12,'市場監控 '!$E$7:$W$194,15,FALSE) -> - | AA12: =VLOOKUP($AD12,'市場監控 '!$E$7:$W$194,17,FALSE) -> #NAME? | AB12: =VLOOKUP($AD12,'市場監控 '!$E$7:$W$194,18,FALSE) -> #NAME? | AC12: =VLOOKUP($AD12,'市場監控 '!$E$7:$W$194,19,FALSE) -> #NAME? | AD12: ACA FP Equity | AE12: 花旗集團 | BB12: =VLOOKUP($BD12,NI!$B$5:$AL$2030,6,FALSE) -> #NAME? | BC12: =VLOOKUP($BD12,NI!$B$37:$AL$2030,2,FALSE) -> #NAME? | BD12: =NI!$B70 -> #NAME? | BE12: =VLOOKUP($BD12,NI!$B$5:$AL$2030,11,FALSE) -> #NAME? | BF12: =VLOOKUP($BD12,NI!$B$5:$AL$2030,12,FALSE)/1000000 -> #NAME? | BH12: =IF(ISNUMBER(VLOOKUP($BD12,NI!$B$5:$AL$2030,13,FALSE)),VLOOKUP($BD12,NI!$B$5:$AL$2030,13,FALSE),"-") -> - | BI12: =VLOOKUP($BD12,NI!$B$5:$AL$2030,4,FALSE) -> #NAME? | BJ12: =VLOOKUP($BD12,NI!$B$5:$AL$2030,3,FALSE) -> #NAME? | BK12: =VLOOKUP($BD12,NI!$B$5:$AL$2030,4,FALSE) -> #NAME? | BL12: =IF(LEFT(VLOOKUP($BD12,NI!$B$5:$AL$2030,31,FALSE),1)="#","-",VLOOKUP($BD12,NI!$B$5:$AL$2030,31,FALSE)) -> #NAME? | BM12: =IF(LEFT(VLOOKUP($BD12,NI!$B$5:$AL$2030,32,FALSE),1)="#","-",VLOOKUP($BD12,NI!$B$5:$AL$2030,32,FALSE)) -> #NAME? | BN12: =IF(LEFT(VLOOKUP($BD12,NI!$B$5:$AL$2030,33,FALSE),1)="#","-",VLOOKUP($BD12,NI!$B$5:$AL$2030,33,FALSE)) -> #NAME? | BO12: =VLOOKUP($BD12,NI!$B$5:$AL$2030,22,FALSE) -> #NAME? | BT12: =VLOOKUP($BV12,TACT!$A$3:$AH$100,2,FALSE) -> #NAME? | BU12: =VLOOKUP($BV12,TACT!$A$3:$AH$100,3,FALSE) -> #NAME? | BV12: =TACT!$A7 -> #NAME? | BW12: =VLOOKUP($BV12,TACT!$A$3:$AH$100,11,FALSE) -> #NAME? | BX12: =VLOOKUP($BV12,TACT!$A$3:$AH$100,5,FALSE) -> #NAME? | BZ12: =VLOOKUP($BV12,TACT!$A$3:$AH$100,4,FALSE) -> #NAME? | CA12: =VLOOKUP($BV12,TACT!$A$3:$AH$100,21,FALSE) -> #NAME? | CB12: =VLOOKUP($BV12,TACT!$A$3:$AH$100,32,FALSE) -> #NAME? | CC12: =VLOOKUP($BV12,TACT!$A$3:$AH$100,33,FALSE) -> #NAME? | CD12: =IF(LEFT(VLOOKUP($BV12,TACT!$A$3:$AH$100,6,FALSE),1)="#","-",VLOOKUP($BV12,TACT!$A$3:$AH$100,6,FALSE)) -> #NAME? | CE12: =IF(LEFT(VLOOKUP($BV12,TACT!$A$3:$AH$100,7,FALSE),1)="#","-",VLOOKUP($BV12,TACT!$A$3:$AH$100,7,FALSE)) -> #NAME? | CF12: =IF(LEFT(VLOOKUP($BV12,TACT!$A$3:$AH$100,8,FALSE),1)="#","-",VLOOKUP($BV12,TACT!$A$3:$AH$100,8,FALSE)) -> #NAME? | EN12: 美國 | EO12: 11 | EP12: 2 | EQ12: 5 | ER12: 主要礦場為加州 Mountain Pass，仍依賴中國精煉
T13: =VLOOKUP($AD13,'市場監控 '!$E$7:$W$194,6,FALSE) -> #NAME? | U13: =VLOOKUP($AD13,'市場監控 '!$E$7:$W$194,7,FALSE) -> #NAME? | V13: =VLOOKUP($AD13,'市場監控 '!$E$7:$W$194,8,FALSE) -> - | W13: =VLOOKUP($AD13,'市場監控 '!$E$7:$W$194,10,FALSE) -> - | X13: =VLOOKUP($AD13,'市場監控 '!$E$7:$W$194,12,FALSE) -> - | Y13: =VLOOKUP($AD13,'市場監控 '!$E$7:$W$194,14,FALSE) -> - | Z13: =VLOOKUP($AD13,'市場監控 '!$E$7:$W$194,15,FALSE) -> - | AA13: =VLOOKUP($AD13,'市場監控 '!$E$7:$W$194,17,FALSE) -> #NAME? | AB13: =VLOOKUP($AD13,'市場監控 '!$E$7:$W$194,18,FALSE) -> #NAME? | AC13: =VLOOKUP($AD13,'市場監控 '!$E$7:$W$194,19,FALSE) -> #NAME? | AD13: KN FP Equity | AE13: 美國銀行 | BB13: =VLOOKUP($BD13,NI!$B$5:$AL$2030,6,FALSE) -> #NAME? | BC13: =VLOOKUP($BD13,NI!$B$37:$AL$2030,2,FALSE) -> #NAME? | BD13: =NI!$B71 -> #NAME? | BE13: =VLOOKUP($BD13,NI!$B$5:$AL$2030,11,FALSE) -> #NAME? | BF13: =VLOOKUP($BD13,NI!$B$5:$AL$2030,12,FALSE)/1000000 -> #NAME? | BH13: =IF(ISNUMBER(VLOOKUP($BD13,NI!$B$5:$AL$2030,13,FALSE)),VLOOKUP($BD13,NI!$B$5:$AL$2030,13,FALSE),"-") -> - | BI13: =VLOOKUP($BD13,NI!$B$5:$AL$2030,4,FALSE) -> #NAME? | BJ13: =VLOOKUP($BD13,NI!$B$5:$AL$2030,3,FALSE) -> #NAME? | BK13: =VLOOKUP($BD13,NI!$B$5:$AL$2030,4,FALSE) -> #NAME? | BL13: =IF(LEFT(VLOOKUP($BD13,NI!$B$5:$AL$2030,31,FALSE),1)="#","-",VLOOKUP($BD13,NI!$B$5:$AL$2030,31,FALSE)) -> #NAME? | BM13: =IF(LEFT(VLOOKUP($BD13,NI!$B$5:$AL$2030,32,FALSE),1)="#","-",VLOOKUP($BD13,NI!$B$5:$AL$2030,32,FALSE)) -> #NAME? | BN13: =IF(LEFT(VLOOKUP($BD13,NI!$B$5:$AL$2030,33,FALSE),1)="#","-",VLOOKUP($BD13,NI!$B$5:$AL$2030,33,FALSE)) -> #NAME? | BO13: =VLOOKUP($BD13,NI!$B$5:$AL$2030,22,FALSE) -> #NAME? | BT13: =VLOOKUP($BV13,TACT!$A$3:$AH$100,2,FALSE) -> #NAME? | BU13: =VLOOKUP($BV13,TACT!$A$3:$AH$100,3,FALSE) -> #NAME? | BV13: =TACT!$A8 -> #NAME? | BW13: =VLOOKUP($BV13,TACT!$A$3:$AH$100,11,FALSE) -> #NAME? | BX13: =VLOOKUP($BV13,TACT!$A$3:$AH$100,5,FALSE) -> #NAME? | BZ13: =VLOOKUP($BV13,TACT!$A$3:$AH$100,4,FALSE) -> #NAME? | CA13: =VLOOKUP($BV13,TACT!$A$3:$AH$100,21,FALSE) -> #NAME? | CB13: =VLOOKUP($BV13,TACT!$A$3:$AH$100,32,FALSE) -> #NAME? | CC13: =VLOOKUP($BV13,TACT!$A$3:$AH$100,33,FALSE) -> #NAME? | CD13: =IF(LEFT(VLOOKUP($BV13,TACT!$A$3:$AH$100,6,FALSE),1)="#","-",VLOOKUP($BV13,TACT!$A$3:$AH$100,6,FALSE)) -> #NAME? | CE13: =IF(LEFT(VLOOKUP($BV13,TACT!$A$3:$AH$100,7,FALSE),1)="#","-",VLOOKUP($BV13,TACT!$A$3:$AH$100,7,FALSE)) -> #NAME? | CF13: =IF(LEFT(VLOOKUP($BV13,TACT!$A$3:$AH$100,8,FALSE),1)="#","-",VLOOKUP($BV13,TACT!$A$3:$AH$100,8,FALSE)) -> #NAME?
T14: =VLOOKUP($AD14,'市場監控 '!$E$7:$W$194,6,FALSE) -> #NAME? | U14: =VLOOKUP($AD14,'市場監控 '!$E$7:$W$194,7,FALSE) -> #NAME? | V14: =VLOOKUP($AD14,'市場監控 '!$E$7:$W$194,8,FALSE) -> - | W14: =VLOOKUP($AD14,'市場監控 '!$E$7:$W$194,10,FALSE) -> - | X14: =VLOOKUP($AD14,'市場監控 '!$E$7:$W$194,12,FALSE) -> - | Y14: =VLOOKUP($AD14,'市場監控 '!$E$7:$W$194,14,FALSE) -> - | Z14: =VLOOKUP($AD14,'市場監控 '!$E$7:$W$194,15,FALSE) -> - | AA14: =VLOOKUP($AD14,'市場監控 '!$E$7:$W$194,17,FALSE) -> #NAME? | AB14: =VLOOKUP($AD14,'市場監控 '!$E$7:$W$194,18,FALSE) -> #NAME? | AC14: =VLOOKUP($AD14,'市場監控 '!$E$7:$W$194,19,FALSE) -> #NAME? | AD14: 3358410Z FP EQUITY | AE14: 摩根大通銀行 | BB14: =VLOOKUP($BD14,NI!$B$5:$AL$2030,6,FALSE) -> #NAME? | BC14: =VLOOKUP($BD14,NI!$B$37:$AL$2030,2,FALSE) -> #NAME? | BD14: =NI!$B72 -> #NAME? | BE14: =VLOOKUP($BD14,NI!$B$5:$AL$2030,11,FALSE) -> #NAME? | BF14: =VLOOKUP($BD14,NI!$B$5:$AL$2030,12,FALSE)/1000000 -> #NAME? | BH14: =IF(ISNUMBER(VLOOKUP($BD14,NI!$B$5:$AL$2030,13,FALSE)),VLOOKUP($BD14,NI!$B$5:$AL$2030,13,FALSE),"-") -> - | BI14: =VLOOKUP($BD14,NI!$B$5:$AL$2030,4,FALSE) -> #NAME? | BJ14: =VLOOKUP($BD14,NI!$B$5:$AL$2030,3,FALSE) -> #NAME? | BK14: =VLOOKUP($BD14,NI!$B$5:$AL$2030,4,FALSE) -> #NAME? | BL14: =IF(LEFT(VLOOKUP($BD14,NI!$B$5:$AL$2030,31,FALSE),1)="#","-",VLOOKUP($BD14,NI!$B$5:$AL$2030,31,FALSE)) -> #NAME? | BM14: =IF(LEFT(VLOOKUP($BD14,NI!$B$5:$AL$2030,32,FALSE),1)="#","-",VLOOKUP($BD14,NI!$B$5:$AL$2030,32,FALSE)) -> #NAME? | BN14: =IF(LEFT(VLOOKUP($BD14,NI!$B$5:$AL$2030,33,FALSE),1)="#","-",VLOOKUP($BD14,NI!$B$5:$AL$2030,33,FALSE)) -> #NAME? | BO14: =VLOOKUP($BD14,NI!$B$5:$AL$2030,22,FALSE) -> #NAME? | BT14: =VLOOKUP($BV14,TACT!$A$3:$AH$100,2,FALSE) -> #NAME? | BU14: =VLOOKUP($BV14,TACT!$A$3:$AH$100,3,FALSE) -> #NAME? | BV14: =TACT!$A9 -> #NAME? | BW14: =VLOOKUP($BV14,TACT!$A$3:$AH$100,11,FALSE) -> #NAME? | BX14: =VLOOKUP($BV14,TACT!$A$3:$AH$100,5,FALSE) -> #NAME? | BZ14: =VLOOKUP($BV14,TACT!$A$3:$AH$100,4,FALSE) -> #NAME? | CA14: =VLOOKUP($BV14,TACT!$A$3:$AH$100,21,FALSE) -> #NAME? | CB14: =VLOOKUP($BV14,TACT!$A$3:$AH$100,32,FALSE) -> #NAME? | CC14: =VLOOKUP($BV14,TACT!$A$3:$AH$100,33,FALSE) -> #NAME? | CD14: =IF(LEFT(VLOOKUP($BV14,TACT!$A$3:$AH$100,6,FALSE),1)="#","-",VLOOKUP($BV14,TACT!$A$3:$AH$100,6,FALSE)) -> #NAME? | CE14: =IF(LEFT(VLOOKUP($BV14,TACT!$A$3:$AH$100,7,FALSE),1)="#","-",VLOOKUP($BV14,TACT!$A$3:$AH$100,7,FALSE)) -> #NAME? | CF14: =IF(LEFT(VLOOKUP($BV14,TACT!$A$3:$AH$100,8,FALSE),1)="#","-",VLOOKUP($BV14,TACT!$A$3:$AH$100,8,FALSE)) -> #NAME?
T15: =VLOOKUP($AD15,'市場監控 '!$E$7:$W$194,6,FALSE) -> #NAME? | U15: =VLOOKUP($AD15,'市場監控 '!$E$7:$W$194,7,FALSE) -> #NAME? | V15: =VLOOKUP($AD15,'市場監控 '!$E$7:$W$194,8,FALSE) -> - | W15: =VLOOKUP($AD15,'市場監控 '!$E$7:$W$194,10,FALSE) -> - | X15: =VLOOKUP($AD15,'市場監控 '!$E$7:$W$194,12,FALSE) -> - | Y15: =VLOOKUP($AD15,'市場監控 '!$E$7:$W$194,14,FALSE) -> - | Z15: =VLOOKUP($AD15,'市場監控 '!$E$7:$W$194,15,FALSE) -> - | AA15: =VLOOKUP($AD15,'市場監控 '!$E$7:$W$194,17,FALSE) -> #NAME? | AB15: =VLOOKUP($AD15,'市場監控 '!$E$7:$W$194,18,FALSE) -> #NAME? | AC15: =VLOOKUP($AD15,'市場監控 '!$E$7:$W$194,19,FALSE) -> #NAME? | AD15: SAN SM Equity | AE15: 富國銀行 | BB15: =VLOOKUP($BD15,NI!$B$5:$AL$2030,6,FALSE) -> #NAME? | BC15: =VLOOKUP($BD15,NI!$B$37:$AL$2030,2,FALSE) -> #NAME? | BD15: =NI!$B73 -> #NAME? | BE15: =VLOOKUP($BD15,NI!$B$5:$AL$2030,11,FALSE) -> #NAME? | BF15: =VLOOKUP($BD15,NI!$B$5:$AL$2030,12,FALSE)/1000000 -> #NAME? | BH15: =IF(ISNUMBER(VLOOKUP($BD15,NI!$B$5:$AL$2030,13,FALSE)),VLOOKUP($BD15,NI!$B$5:$AL$2030,13,FALSE),"-") -> - | BI15: =VLOOKUP($BD15,NI!$B$5:$AL$2030,4,FALSE) -> #NAME? | BJ15: =VLOOKUP($BD15,NI!$B$5:$AL$2030,3,FALSE) -> #NAME? | BK15: =VLOOKUP($BD15,NI!$B$5:$AL$2030,4,FALSE) -> #NAME? | BL15: =IF(LEFT(VLOOKUP($BD15,NI!$B$5:$AL$2030,31,FALSE),1)="#","-",VLOOKUP($BD15,NI!$B$5:$AL$2030,31,FALSE)) -> #NAME? | BM15: =IF(LEFT(VLOOKUP($BD15,NI!$B$5:$AL$2030,32,FALSE),1)="#","-",VLOOKUP($BD15,NI!$B$5:$AL$2030,32,FALSE)) -> #NAME? | BN15: =IF(LEFT(VLOOKUP($BD15,NI!$B$5:$AL$2030,33,FALSE),1)="#","-",VLOOKUP($BD15,NI!$B$5:$AL$2030,33,FALSE)) -> #NAME? | BO15: =VLOOKUP($BD15,NI!$B$5:$AL$2030,22,FALSE) -> #NAME? | BT15: =VLOOKUP($BV15,TACT!$A$3:$AH$100,2,FALSE) -> #NAME? | BU15: =VLOOKUP($BV15,TACT!$A$3:$AH$100,3,FALSE) -> #NAME? | BV15: =TACT!$A10 -> #NAME? | BW15: =VLOOKUP($BV15,TACT!$A$3:$AH$100,11,FALSE) -> #NAME? | BX15: =VLOOKUP($BV15,TACT!$A$3:$AH$100,5,FALSE) -> #NAME? | BZ15: =VLOOKUP($BV15,TACT!$A$3:$AH$100,4,FALSE) -> #NAME? | CA15: =VLOOKUP($BV15,TACT!$A$3:$AH$100,21,FALSE) -> #NAME? | CB15: =VLOOKUP($BV15,TACT!$A$3:$AH$100,32,FALSE) -> #NAME? | CC15: =VLOOKUP($BV15,TACT!$A$3:$AH$100,33,FALSE) -> #NAME? | CD15: =IF(LEFT(VLOOKUP($BV15,TACT!$A$3:$AH$100,6,FALSE),1)="#","-",VLOOKUP($BV15,TACT!$A$3:$AH$100,6,FALSE)) -> #NAME? | CE15: =IF(LEFT(VLOOKUP($BV15,TACT!$A$3:$AH$100,7,FALSE),1)="#","-",VLOOKUP($BV15,TACT!$A$3:$AH$100,7,FALSE)) -> #NAME? | CF15: =IF(LEFT(VLOOKUP($BV15,TACT!$A$3:$AH$100,8,FALSE),1)="#","-",VLOOKUP($BV15,TACT!$A$3:$AH$100,8,FALSE)) -> #NAME? | EN15: 澳洲 | EO15: 5 | EP15: 3 | EQ15: 4 | ER15: 擁有全球第4大蘊藏量，積極擴產與建精煉廠
T16: =VLOOKUP($AD16,'市場監控 '!$E$7:$W$194,6,FALSE) -> #NAME? | U16: =VLOOKUP($AD16,'市場監控 '!$E$7:$W$194,7,FALSE) -> #NAME? | V16: =VLOOKUP($AD16,'市場監控 '!$E$7:$W$194,8,FALSE) -> - | W16: =VLOOKUP($AD16,'市場監控 '!$E$7:$W$194,10,FALSE) -> - | X16: =VLOOKUP($AD16,'市場監控 '!$E$7:$W$194,12,FALSE) -> - | Y16: =VLOOKUP($AD16,'市場監控 '!$E$7:$W$194,14,FALSE) -> - | Z16: =VLOOKUP($AD16,'市場監控 '!$E$7:$W$194,15,FALSE) -> - | AA16: =VLOOKUP($AD16,'市場監控 '!$E$7:$W$194,17,FALSE) -> #NAME? | AB16: =VLOOKUP($AD16,'市場監控 '!$E$7:$W$194,18,FALSE) -> #NAME? | AC16: =VLOOKUP($AD16,'市場監控 '!$E$7:$W$194,19,FALSE) -> #NAME? | AD16: 3988 HK Equity | AE16: 高盛集團 | BB16: =VLOOKUP($BD16,NI!$B$5:$AL$2030,6,FALSE) -> #NAME? | BC16: =VLOOKUP($BD16,NI!$B$37:$AL$2030,2,FALSE) -> #NAME? | BD16: =NI!$B74 -> #NAME? | BE16: =VLOOKUP($BD16,NI!$B$5:$AL$2030,11,FALSE) -> #NAME? | BF16: =VLOOKUP($BD16,NI!$B$5:$AL$2030,12,FALSE)/1000000 -> #NAME? | BH16: =IF(ISNUMBER(VLOOKUP($BD16,NI!$B$5:$AL$2030,13,FALSE)),VLOOKUP($BD16,NI!$B$5:$AL$2030,13,FALSE),"-") -> - | BI16: =VLOOKUP($BD16,NI!$B$5:$AL$2030,4,FALSE) -> #NAME? | BJ16: =VLOOKUP($BD16,NI!$B$5:$AL$2030,3,FALSE) -> #NAME? | BK16: =VLOOKUP($BD16,NI!$B$5:$AL$2030,4,FALSE) -> #NAME? | BL16: =IF(LEFT(VLOOKUP($BD16,NI!$B$5:$AL$2030,31,FALSE),1)="#","-",VLOOKUP($BD16,NI!$B$5:$AL$2030,31,FALSE)) -> #NAME? | BM16: =IF(LEFT(VLOOKUP($BD16,NI!$B$5:$AL$2030,32,FALSE),1)="#","-",VLOOKUP($BD16,NI!$B$5:$AL$2030,32,FALSE)) -> #NAME? | BN16: =IF(LEFT(VLOOKUP($BD16,NI!$B$5:$AL$2030,33,FALSE),1)="#","-",VLOOKUP($BD16,NI!$B$5:$AL$2030,33,FALSE)) -> #NAME? | BO16: =VLOOKUP($BD16,NI!$B$5:$AL$2030,22,FALSE) -> #NAME? | BT16: =VLOOKUP($BV16,TACT!$A$3:$AH$100,2,FALSE) -> #NAME? | BU16: =VLOOKUP($BV16,TACT!$A$3:$AH$100,3,FALSE) -> #NAME? | BV16: =TACT!$A11 -> #NAME? | BW16: =VLOOKUP($BV16,TACT!$A$3:$AH$100,11,FALSE) -> #NAME? | BX16: =VLOOKUP($BV16,TACT!$A$3:$AH$100,5,FALSE) -> #NAME? | BZ16: =VLOOKUP($BV16,TACT!$A$3:$AH$100,4,FALSE) -> #NAME? | CA16: =VLOOKUP($BV16,TACT!$A$3:$AH$100,21,FALSE) -> #NAME? | CB16: =VLOOKUP($BV16,TACT!$A$3:$AH$100,32,FALSE) -> #NAME? | CC16: =VLOOKUP($BV16,TACT!$A$3:$AH$100,33,FALSE) -> #NAME? | CD16: =IF(LEFT(VLOOKUP($BV16,TACT!$A$3:$AH$100,6,FALSE),1)="#","-",VLOOKUP($BV16,TACT!$A$3:$AH$100,6,FALSE)) -> #NAME? | CE16: =IF(LEFT(VLOOKUP($BV16,TACT!$A$3:$AH$100,7,FALSE),1)="#","-",VLOOKUP($BV16,TACT!$A$3:$AH$100,7,FALSE)) -> #NAME? | CF16: =IF(LEFT(VLOOKUP($BV16,TACT!$A$3:$AH$100,8,FALSE),1)="#","-",VLOOKUP($BV16,TACT!$A$3:$AH$100,8,FALSE)) -> #NAME?
T17: =VLOOKUP($AD17,'市場監控 '!$E$7:$W$194,6,FALSE) -> #NAME? | U17: =VLOOKUP($AD17,'市場監控 '!$E$7:$W$194,7,FALSE) -> #NAME? | V17: =VLOOKUP($AD17,'市場監控 '!$E$7:$W$194,8,FALSE) -> - | W17: =VLOOKUP($AD17,'市場監控 '!$E$7:$W$194,10,FALSE) -> - | X17: =VLOOKUP($AD17,'市場監控 '!$E$7:$W$194,12,FALSE) -> - | Y17: =VLOOKUP($AD17,'市場監控 '!$E$7:$W$194,14,FALSE) -> - | Z17: =VLOOKUP($AD17,'市場監控 '!$E$7:$W$194,15,FALSE) -> - | AA17: =VLOOKUP($AD17,'市場監控 '!$E$7:$W$194,17,FALSE) -> #NAME? | AB17: =VLOOKUP($AD17,'市場監控 '!$E$7:$W$194,18,FALSE) -> #NAME? | AC17: =VLOOKUP($AD17,'市場監控 '!$E$7:$W$194,19,FALSE) -> #NAME? | AD17: 1398 HK Equity | AE17: 摩根士丹利 | BB17: =VLOOKUP($BD17,NI!$B$5:$AL$2030,6,FALSE) -> #NAME? | BC17: =VLOOKUP($BD17,NI!$B$37:$AL$2030,2,FALSE) -> #NAME? | BD17: =NI!$B75 -> #NAME? | BE17: =VLOOKUP($BD17,NI!$B$5:$AL$2030,11,FALSE) -> #NAME? | BF17: =VLOOKUP($BD17,NI!$B$5:$AL$2030,12,FALSE)/1000000 -> #NAME? | BH17: =IF(ISNUMBER(VLOOKUP($BD17,NI!$B$5:$AL$2030,13,FALSE)),VLOOKUP($BD17,NI!$B$5:$AL$2030,13,FALSE),"-") -> - | BI17: =VLOOKUP($BD17,NI!$B$5:$AL$2030,4,FALSE) -> #NAME? | BJ17: =VLOOKUP($BD17,NI!$B$5:$AL$2030,3,FALSE) -> #NAME? | BK17: =VLOOKUP($BD17,NI!$B$5:$AL$2030,4,FALSE) -> #NAME? | BL17: =IF(LEFT(VLOOKUP($BD17,NI!$B$5:$AL$2030,31,FALSE),1)="#","-",VLOOKUP($BD17,NI!$B$5:$AL$2030,31,FALSE)) -> #NAME? | BM17: =IF(LEFT(VLOOKUP($BD17,NI!$B$5:$AL$2030,32,FALSE),1)="#","-",VLOOKUP($BD17,NI!$B$5:$AL$2030,32,FALSE)) -> #NAME? | BN17: =IF(LEFT(VLOOKUP($BD17,NI!$B$5:$AL$2030,33,FALSE),1)="#","-",VLOOKUP($BD17,NI!$B$5:$AL$2030,33,FALSE)) -> #NAME? | BO17: =VLOOKUP($BD17,NI!$B$5:$AL$2030,22,FALSE) -> #NAME? | BT17: =VLOOKUP($BV17,TACT!$A$3:$AH$100,2,FALSE) -> #NAME? | BU17: =VLOOKUP($BV17,TACT!$A$3:$AH$100,3,FALSE) -> #NAME? | BV17: =TACT!$A12 -> #NAME? | BW17: =VLOOKUP($BV17,TACT!$A$3:$AH$100,11,FALSE) -> #NAME? | BX17: =VLOOKUP($BV17,TACT!$A$3:$AH$100,5,FALSE) -> #NAME? | BZ17: =VLOOKUP($BV17,TACT!$A$3:$AH$100,4,FALSE) -> #NAME? | CA17: =VLOOKUP($BV17,TACT!$A$3:$AH$100,21,FALSE) -> #NAME? | CB17: =VLOOKUP($BV17,TACT!$A$3:$AH$100,32,FALSE) -> #NAME? | CC17: =VLOOKUP($BV17,TACT!$A$3:$AH$100,33,FALSE) -> #NAME? | CD17: =IF(LEFT(VLOOKUP($BV17,TACT!$A$3:$AH$100,6,FALSE),1)="#","-",VLOOKUP($BV17,TACT!$A$3:$AH$100,6,FALSE)) -> #NAME? | CE17: =IF(LEFT(VLOOKUP($BV17,TACT!$A$3:$AH$100,7,FALSE),1)="#","-",VLOOKUP($BV17,TACT!$A$3:$AH$100,7,FALSE)) -> #NAME? | CF17: =IF(LEFT(VLOOKUP($BV17,TACT!$A$3:$AH$100,8,FALSE),1)="#","-",VLOOKUP($BV17,TACT!$A$3:$AH$100,8,FALSE)) -> #NAME? | EX17: 區域性銀行信貸踩雷 | EZ17: 2025年10月 | FA17: 1. Zions Bancorp與Western Alliance Bancorp爆出貸款損失，部分與Tricolor、First Brands有關。 2. 涉及非存款類金融機構（NDFI）貸款，與私募信貸密切相關。 | FD17: 1. Zions股價暴跌13%，WAL跌逾10%，區域銀行ETF（KRE）單日跌幅達6.2% 2. KBW區域銀行指數創半年最大跌幅。 3. 市場避險情緒升溫，VIX指數飆升。 | FH17: 投資人擔憂私募信貸風險擴散至銀行體系。
T18: =VLOOKUP($AD18,'市場監控 '!$E$7:$W$194,6,FALSE) -> #NAME? | U18: =VLOOKUP($AD18,'市場監控 '!$E$7:$W$194,7,FALSE) -> #NAME? | V18: =VLOOKUP($AD18,'市場監控 '!$E$7:$W$194,8,FALSE) -> - | W18: =VLOOKUP($AD18,'市場監控 '!$E$7:$W$194,10,FALSE) -> - | X18: =VLOOKUP($AD18,'市場監控 '!$E$7:$W$194,12,FALSE) -> - | Y18: =VLOOKUP($AD18,'市場監控 '!$E$7:$W$194,14,FALSE) -> - | Z18: =VLOOKUP($AD18,'市場監控 '!$E$7:$W$194,15,FALSE) -> - | AA18: =VLOOKUP($AD18,'市場監控 '!$E$7:$W$194,17,FALSE) -> #NAME? | AB18: =VLOOKUP($AD18,'市場監控 '!$E$7:$W$194,18,FALSE) -> #NAME? | AC18: =VLOOKUP($AD18,'市場監控 '!$E$7:$W$194,19,FALSE) -> #NAME? | AD18: 939 HK Equity | AE18: 法國巴黎銀行 | BB18: =VLOOKUP($BD18,NI!$B$5:$AL$2030,6,FALSE) -> #NAME? | BC18: =VLOOKUP($BD18,NI!$B$37:$AL$2030,2,FALSE) -> #NAME? | BD18: =NI!$B76 -> #NAME? | BE18: =VLOOKUP($BD18,NI!$B$5:$AL$2030,11,FALSE) -> #NAME? | BF18: =VLOOKUP($BD18,NI!$B$5:$AL$2030,12,FALSE)/1000000 -> #NAME? | BH18: =IF(ISNUMBER(VLOOKUP($BD18,NI!$B$5:$AL$2030,13,FALSE)),VLOOKUP($BD18,NI!$B$5:$AL$2030,13,FALSE),"-") -> - | BI18: =VLOOKUP($BD18,NI!$B$5:$AL$2030,4,FALSE) -> #NAME? | BJ18: =VLOOKUP($BD18,NI!$B$5:$AL$2030,3,FALSE) -> #NAME? | BK18: =VLOOKUP($BD18,NI!$B$5:$AL$2030,4,FALSE) -> #NAME? | BL18: =IF(LEFT(VLOOKUP($BD18,NI!$B$5:$AL$2030,31,FALSE),1)="#","-",VLOOKUP($BD18,NI!$B$5:$AL$2030,31,FALSE)) -> #NAME? | BM18: =IF(LEFT(VLOOKUP($BD18,NI!$B$5:$AL$2030,32,FALSE),1)="#","-",VLOOKUP($BD18,NI!$B$5:$AL$2030,32,FALSE)) -> #NAME? | BN18: =IF(LEFT(VLOOKUP($BD18,NI!$B$5:$AL$2030,33,FALSE),1)="#","-",VLOOKUP($BD18,NI!$B$5:$AL$2030,33,FALSE)) -> #NAME? | BO18: =VLOOKUP($BD18,NI!$B$5:$AL$2030,22,FALSE) -> #NAME? | BT18: =VLOOKUP($BV18,TACT!$A$3:$AH$100,2,FALSE) -> #NAME? | BU18: =VLOOKUP($BV18,TACT!$A$3:$AH$100,3,FALSE) -> #NAME? | BV18: =TACT!$A13 -> #NAME? | BW18: =VLOOKUP($BV18,TACT!$A$3:$AH$100,11,FALSE) -> #NAME? | BX18: =VLOOKUP($BV18,TACT!$A$3:$AH$100,5,FALSE) -> #NAME? | BZ18: =VLOOKUP($BV18,TACT!$A$3:$AH$100,4,FALSE) -> #NAME? | CA18: =VLOOKUP($BV18,TACT!$A$3:$AH$100,21,FALSE) -> #NAME? | CB18: =VLOOKUP($BV18,TACT!$A$3:$AH$100,32,FALSE) -> #NAME? | CC18: =VLOOKUP($BV18,TACT!$A$3:$AH$100,33,FALSE) -> #NAME? | CD18: =IF(LEFT(VLOOKUP($BV18,TACT!$A$3:$AH$100,6,FALSE),1)="#","-",VLOOKUP($BV18,TACT!$A$3:$AH$100,6,FALSE)) -> #NAME? | CE18: =IF(LEFT(VLOOKUP($BV18,TACT!$A$3:$AH$100,7,FALSE),1)="#","-",VLOOKUP($BV18,TACT!$A$3:$AH$100,7,FALSE)) -> #NAME? | CF18: =IF(LEFT(VLOOKUP($BV18,TACT!$A$3:$AH$100,8,FALSE),1)="#","-",VLOOKUP($BV18,TACT!$A$3:$AH$100,8,FALSE)) -> #NAME? | EN18: 緬甸與東南亞 | EO18: 10 | EP18: 2 | EQ18: 10 | ER18: 向中國出口氧化物或原礦，部分具初步分離能力
T19: =VLOOKUP($AD19,'市場監控 '!$E$7:$W$194,6,FALSE) -> #NAME? | U19: =VLOOKUP($AD19,'市場監控 '!$E$7:$W$194,7,FALSE) -> #NAME? | V19: =VLOOKUP($AD19,'市場監控 '!$E$7:$W$194,8,FALSE) -> - | W19: =VLOOKUP($AD19,'市場監控 '!$E$7:$W$194,10,FALSE) -> - | X19: =VLOOKUP($AD19,'市場監控 '!$E$7:$W$194,12,FALSE) -> - | Y19: =VLOOKUP($AD19,'市場監控 '!$E$7:$W$194,14,FALSE) -> - | Z19: =VLOOKUP($AD19,'市場監控 '!$E$7:$W$194,15,FALSE) -> - | AA19: =VLOOKUP($AD19,'市場監控 '!$E$7:$W$194,17,FALSE) -> #NAME? | AB19: =VLOOKUP($AD19,'市場監控 '!$E$7:$W$194,18,FALSE) -> #NAME? | AC19: =VLOOKUP($AD19,'市場監控 '!$E$7:$W$194,19,FALSE) -> #NAME? | AD19: 601288 CH Equity | AE19: 法國興業銀行 | BB19: =VLOOKUP($BD19,NI!$B$5:$AL$2030,6,FALSE) -> #NAME? | BC19: =VLOOKUP($BD19,NI!$B$37:$AL$2030,2,FALSE) -> #NAME? | BD19: =NI!$B77 -> #NAME? | BE19: =VLOOKUP($BD19,NI!$B$5:$AL$2030,11,FALSE) -> #NAME? | BF19: =VLOOKUP($BD19,NI!$B$5:$AL$2030,12,FALSE)/1000000 -> #NAME? | BH19: =IF(ISNUMBER(VLOOKUP($BD19,NI!$B$5:$AL$2030,13,FALSE)),VLOOKUP($BD19,NI!$B$5:$AL$2030,13,FALSE),"-") -> - | BI19: =VLOOKUP($BD19,NI!$B$5:$AL$2030,4,FALSE) -> #NAME? | BJ19: =VLOOKUP($BD19,NI!$B$5:$AL$2030,3,FALSE) -> #NAME? | BK19: =VLOOKUP($BD19,NI!$B$5:$AL$2030,4,FALSE) -> #NAME? | BL19: =IF(LEFT(VLOOKUP($BD19,NI!$B$5:$AL$2030,31,FALSE),1)="#","-",VLOOKUP($BD19,NI!$B$5:$AL$2030,31,FALSE)) -> #NAME? | BM19: =IF(LEFT(VLOOKUP($BD19,NI!$B$5:$AL$2030,32,FALSE),1)="#","-",VLOOKUP($BD19,NI!$B$5:$AL$2030,32,FALSE)) -> #NAME? | BN19: =IF(LEFT(VLOOKUP($BD19,NI!$B$5:$AL$2030,33,FALSE),1)="#","-",VLOOKUP($BD19,NI!$B$5:$AL$2030,33,FALSE)) -> #NAME? | BO19: =VLOOKUP($BD19,NI!$B$5:$AL$2030,22,FALSE) -> #NAME? | BT19: =VLOOKUP($BV19,TACT!$A$3:$AH$100,2,FALSE) -> #NAME? | BU19: =VLOOKUP($BV19,TACT!$A$3:$AH$100,3,FALSE) -> #NAME? | BV19: =TACT!$A14 -> #NAME? | BW19: =VLOOKUP($BV19,TACT!$A$3:$AH$100,11,FALSE) -> #NAME? | BX19: =VLOOKUP($BV19,TACT!$A$3:$AH$100,5,FALSE) -> #NAME? | BZ19: =VLOOKUP($BV19,TACT!$A$3:$AH$100,4,FALSE) -> #NAME? | CA19: =VLOOKUP($BV19,TACT!$A$3:$AH$100,21,FALSE) -> #NAME? | CB19: =VLOOKUP($BV19,TACT!$A$3:$AH$100,32,FALSE) -> #NAME? | CC19: =VLOOKUP($BV19,TACT!$A$3:$AH$100,33,FALSE) -> #NAME? | CD19: =IF(LEFT(VLOOKUP($BV19,TACT!$A$3:$AH$100,6,FALSE),1)="#","-",VLOOKUP($BV19,TACT!$A$3:$AH$100,6,FALSE)) -> #NAME? | CE19: =IF(LEFT(VLOOKUP($BV19,TACT!$A$3:$AH$100,7,FALSE),1)="#","-",VLOOKUP($BV19,TACT!$A$3:$AH$100,7,FALSE)) -> #NAME? | CF19: =IF(LEFT(VLOOKUP($BV19,TACT!$A$3:$AH$100,8,FALSE),1)="#","-",VLOOKUP($BV19,TACT!$A$3:$AH$100,8,FALSE)) -> #NAME?
T20: =VLOOKUP($AD20,'市場監控 '!$E$7:$W$194,6,FALSE) -> #NAME? | U20: =VLOOKUP($AD20,'市場監控 '!$E$7:$W$194,7,FALSE) -> #NAME? | V20: =VLOOKUP($AD20,'市場監控 '!$E$7:$W$194,8,FALSE) -> - | W20: =VLOOKUP($AD20,'市場監控 '!$E$7:$W$194,10,FALSE) -> - | X20: =VLOOKUP($AD20,'市場監控 '!$E$7:$W$194,12,FALSE) -> - | Y20: =VLOOKUP($AD20,'市場監控 '!$E$7:$W$194,14,FALSE) -> - | Z20: =VLOOKUP($AD20,'市場監控 '!$E$7:$W$194,15,FALSE) -> - | AA20: =VLOOKUP($AD20,'市場監控 '!$E$7:$W$194,17,FALSE) -> #NAME? | AB20: =VLOOKUP($AD20,'市場監控 '!$E$7:$W$194,18,FALSE) -> #NAME? | AC20: =VLOOKUP($AD20,'市場監控 '!$E$7:$W$194,19,FALSE) -> #NAME? | AD20: JPM US Equity | AE20: 法國農業信貸銀行 | BB20: =VLOOKUP($BD20,NI!$B$5:$AL$2030,6,FALSE) -> #NAME? | BC20: =VLOOKUP($BD20,NI!$B$37:$AL$2030,2,FALSE) -> #NAME? | BD20: =NI!$B78 -> #NAME? | BE20: =VLOOKUP($BD20,NI!$B$5:$AL$2030,11,FALSE) -> #NAME? | BF20: =VLOOKUP($BD20,NI!$B$5:$AL$2030,12,FALSE)/1000000 -> #NAME? | BH20: =IF(ISNUMBER(VLOOKUP($BD20,NI!$B$5:$AL$2030,13,FALSE)),VLOOKUP($BD20,NI!$B$5:$AL$2030,13,FALSE),"-") -> - | BI20: =VLOOKUP($BD20,NI!$B$5:$AL$2030,4,FALSE) -> #NAME? | BJ20: =VLOOKUP($BD20,NI!$B$5:$AL$2030,3,FALSE) -> #NAME? | BK20: =VLOOKUP($BD20,NI!$B$5:$AL$2030,4,FALSE) -> #NAME? | BL20: =IF(LEFT(VLOOKUP($BD20,NI!$B$5:$AL$2030,31,FALSE),1)="#","-",VLOOKUP($BD20,NI!$B$5:$AL$2030,31,FALSE)) -> #NAME? | BM20: =IF(LEFT(VLOOKUP($BD20,NI!$B$5:$AL$2030,32,FALSE),1)="#","-",VLOOKUP($BD20,NI!$B$5:$AL$2030,32,FALSE)) -> #NAME? | BN20: =IF(LEFT(VLOOKUP($BD20,NI!$B$5:$AL$2030,33,FALSE),1)="#","-",VLOOKUP($BD20,NI!$B$5:$AL$2030,33,FALSE)) -> #NAME? | BO20: =VLOOKUP($BD20,NI!$B$5:$AL$2030,22,FALSE) -> #NAME? | BT20: =VLOOKUP($BV20,TACT!$A$3:$AH$100,2,FALSE) -> #NAME? | BU20: =VLOOKUP($BV20,TACT!$A$3:$AH$100,3,FALSE) -> #NAME? | BV20: =TACT!$A15 -> #NAME? | BW20: =VLOOKUP($BV20,TACT!$A$3:$AH$100,11,FALSE) -> #NAME? | BX20: =VLOOKUP($BV20,TACT!$A$3:$AH$100,5,FALSE) -> #NAME? | BZ20: =VLOOKUP($BV20,TACT!$A$3:$AH$100,4,FALSE) -> #NAME? | CA20: =VLOOKUP($BV20,TACT!$A$3:$AH$100,21,FALSE) -> #NAME? | CB20: =VLOOKUP($BV20,TACT!$A$3:$AH$100,32,FALSE) -> #NAME? | CC20: =VLOOKUP($BV20,TACT!$A$3:$AH$100,33,FALSE) -> #NAME? | CD20: =IF(LEFT(VLOOKUP($BV20,TACT!$A$3:$AH$100,6,FALSE),1)="#","-",VLOOKUP($BV20,TACT!$A$3:$AH$100,6,FALSE)) -> #NAME? | CE20: =IF(LEFT(VLOOKUP($BV20,TACT!$A$3:$AH$100,7,FALSE),1)="#","-",VLOOKUP($BV20,TACT!$A$3:$AH$100,7,FALSE)) -> #NAME? | CF20: =IF(LEFT(VLOOKUP($BV20,TACT!$A$3:$AH$100,8,FALSE),1)="#","-",VLOOKUP($BV20,TACT!$A$3:$AH$100,8,FALSE)) -> #NAME?
T21: =VLOOKUP($AD21,'市場監控 '!$E$7:$W$194,6,FALSE) -> #NAME? | U21: =VLOOKUP($AD21,'市場監控 '!$E$7:$W$194,7,FALSE) -> #NAME? | V21: =VLOOKUP($AD21,'市場監控 '!$E$7:$W$194,8,FALSE) -> - | W21: =VLOOKUP($AD21,'市場監控 '!$E$7:$W$194,10,FALSE) -> - | X21: =VLOOKUP($AD21,'市場監控 '!$E$7:$W$194,12,FALSE) -> - | Y21: =VLOOKUP($AD21,'市場監控 '!$E$7:$W$194,14,FALSE) -> - | Z21: =VLOOKUP($AD21,'市場監控 '!$E$7:$W$194,15,FALSE) -> - | AA21: =VLOOKUP($AD21,'市場監控 '!$E$7:$W$194,17,FALSE) -> #NAME? | AB21: =VLOOKUP($AD21,'市場監控 '!$E$7:$W$194,18,FALSE) -> #NAME? | AC21: =VLOOKUP($AD21,'市場監控 '!$E$7:$W$194,19,FALSE) -> #NAME? | AD21: GLE FP Equity | AE21: 法國外貿銀行股份有限公司 | BB21: =VLOOKUP($BD21,NI!$B$5:$AL$2030,6,FALSE) -> #NAME? | BC21: =VLOOKUP($BD21,NI!$B$37:$AL$2030,2,FALSE) -> #NAME? | BD21: =NI!$B79 -> #NAME? | BE21: =VLOOKUP($BD21,NI!$B$5:$AL$2030,11,FALSE) -> #NAME? | BF21: =VLOOKUP($BD21,NI!$B$5:$AL$2030,12,FALSE)/1000000 -> #NAME? | BH21: =IF(ISNUMBER(VLOOKUP($BD21,NI!$B$5:$AL$2030,13,FALSE)),VLOOKUP($BD21,NI!$B$5:$AL$2030,13,FALSE),"-") -> - | BI21: =VLOOKUP($BD21,NI!$B$5:$AL$2030,4,FALSE) -> #NAME? | BJ21: =VLOOKUP($BD21,NI!$B$5:$AL$2030,3,FALSE) -> #NAME? | BK21: =VLOOKUP($BD21,NI!$B$5:$AL$2030,4,FALSE) -> #NAME? | BL21: =IF(LEFT(VLOOKUP($BD21,NI!$B$5:$AL$2030,31,FALSE),1)="#","-",VLOOKUP($BD21,NI!$B$5:$AL$2030,31,FALSE)) -> #NAME? | BM21: =IF(LEFT(VLOOKUP($BD21,NI!$B$5:$AL$2030,32,FALSE),1)="#","-",VLOOKUP($BD21,NI!$B$5:$AL$2030,32,FALSE)) -> #NAME? | BN21: =IF(LEFT(VLOOKUP($BD21,NI!$B$5:$AL$2030,33,FALSE),1)="#","-",VLOOKUP($BD21,NI!$B$5:$AL$2030,33,FALSE)) -> #NAME? | BO21: =VLOOKUP($BD21,NI!$B$5:$AL$2030,22,FALSE) -> #NAME? | BT21: =VLOOKUP($BV21,TACT!$A$3:$AH$100,2,FALSE) -> #NAME? | BU21: =VLOOKUP($BV21,TACT!$A$3:$AH$100,3,FALSE) -> #NAME? | BV21: =TACT!$A16 -> #NAME? | BW21: =VLOOKUP($BV21,TACT!$A$3:$AH$100,11,FALSE) -> #NAME? | BX21: =VLOOKUP($BV21,TACT!$A$3:$AH$100,5,FALSE) -> #NAME? | BZ21: =VLOOKUP($BV21,TACT!$A$3:$AH$100,4,FALSE) -> #NAME? | CA21: =VLOOKUP($BV21,TACT!$A$3:$AH$100,21,FALSE) -> #NAME? | CB21: =VLOOKUP($BV21,TACT!$A$3:$AH$100,32,FALSE) -> #NAME? | CC21: =VLOOKUP($BV21,TACT!$A$3:$AH$100,33,FALSE) -> #NAME? | CD21: =IF(LEFT(VLOOKUP($BV21,TACT!$A$3:$AH$100,6,FALSE),1)="#","-",VLOOKUP($BV21,TACT!$A$3:$AH$100,6,FALSE)) -> #NAME? | CE21: =IF(LEFT(VLOOKUP($BV21,TACT!$A$3:$AH$100,7,FALSE),1)="#","-",VLOOKUP($BV21,TACT!$A$3:$AH$100,7,FALSE)) -> #NAME? | CF21: =IF(LEFT(VLOOKUP($BV21,TACT!$A$3:$AH$100,8,FALSE),1)="#","-",VLOOKUP($BV21,TACT!$A$3:$AH$100,8,FALSE)) -> #NAME? | EN21: 加拿大 | EO21: 7 | EP21: 2 | EQ21: 3 | ER21: 擁有全球最大稀土氧化物蘊藏量之一，尚在開發階段
T22: =VLOOKUP($AD22,'市場監控 '!$E$7:$W$194,6,FALSE) -> #NAME? | U22: =VLOOKUP($AD22,'市場監控 '!$E$7:$W$194,7,FALSE) -> #NAME? | V22: =VLOOKUP($AD22,'市場監控 '!$E$7:$W$194,8,FALSE) -> - | W22: =VLOOKUP($AD22,'市場監控 '!$E$7:$W$194,10,FALSE) -> - | X22: =VLOOKUP($AD22,'市場監控 '!$E$7:$W$194,12,FALSE) -> - | Y22: =VLOOKUP($AD22,'市場監控 '!$E$7:$W$194,14,FALSE) -> - | Z22: =VLOOKUP($AD22,'市場監控 '!$E$7:$W$194,15,FALSE) -> - | AA22: =VLOOKUP($AD22,'市場監控 '!$E$7:$W$194,17,FALSE) -> #NAME? | AB22: =VLOOKUP($AD22,'市場監控 '!$E$7:$W$194,18,FALSE) -> #NAME? | AC22: =VLOOKUP($AD22,'市場監控 '!$E$7:$W$194,19,FALSE) -> #NAME? | AD22: DBK GR Equity | AE22: BPCE有限責任公司 | BB22: =VLOOKUP($BD22,NI!$B$5:$AL$2030,6,FALSE) -> #NAME? | BC22: =VLOOKUP($BD22,NI!$B$37:$AL$2030,2,FALSE) -> #NAME? | BD22: =NI!$B80 -> #NAME? | BE22: =VLOOKUP($BD22,NI!$B$5:$AL$2030,11,FALSE) -> #NAME? | BF22: =VLOOKUP($BD22,NI!$B$5:$AL$2030,12,FALSE)/1000000 -> #NAME? | BH22: =IF(ISNUMBER(VLOOKUP($BD22,NI!$B$5:$AL$2030,13,FALSE)),VLOOKUP($BD22,NI!$B$5:$AL$2030,13,FALSE),"-") -> - | BI22: =VLOOKUP($BD22,NI!$B$5:$AL$2030,4,FALSE) -> #NAME? | BJ22: =VLOOKUP($BD22,NI!$B$5:$AL$2030,3,FALSE) -> #NAME? | BK22: =VLOOKUP($BD22,NI!$B$5:$AL$2030,4,FALSE) -> #NAME? | BL22: =IF(LEFT(VLOOKUP($BD22,NI!$B$5:$AL$2030,31,FALSE),1)="#","-",VLOOKUP($BD22,NI!$B$5:$AL$2030,31,FALSE)) -> #NAME? | BM22: =IF(LEFT(VLOOKUP($BD22,NI!$B$5:$AL$2030,32,FALSE),1)="#","-",VLOOKUP($BD22,NI!$B$5:$AL$2030,32,FALSE)) -> #NAME? | BN22: =IF(LEFT(VLOOKUP($BD22,NI!$B$5:$AL$2030,33,FALSE),1)="#","-",VLOOKUP($BD22,NI!$B$5:$AL$2030,33,FALSE)) -> #NAME? | BO22: =VLOOKUP($BD22,NI!$B$5:$AL$2030,22,FALSE) -> #NAME? | BT22: =VLOOKUP($BV22,TACT!$A$3:$AH$100,2,FALSE) -> #NAME? | BU22: =VLOOKUP($BV22,TACT!$A$3:$AH$100,3,FALSE) -> #NAME? | BV22: =TACT!$A17 -> #NAME? | BW22: =VLOOKUP($BV22,TACT!$A$3:$AH$100,11,FALSE) -> #NAME? | BX22: =VLOOKUP($BV22,TACT!$A$3:$AH$100,5,FALSE) -> #NAME? | BZ22: =VLOOKUP($BV22,TACT!$A$3:$AH$100,4,FALSE) -> #NAME? | CA22: =VLOOKUP($BV22,TACT!$A$3:$AH$100,21,FALSE) -> #NAME? | CB22: =VLOOKUP($BV22,TACT!$A$3:$AH$100,32,FALSE) -> #NAME? | CC22: =VLOOKUP($BV22,TACT!$A$3:$AH$100,33,FALSE) -> #NAME? | CD22: =IF(LEFT(VLOOKUP($BV22,TACT!$A$3:$AH$100,6,FALSE),1)="#","-",VLOOKUP($BV22,TACT!$A$3:$AH$100,6,FALSE)) -> #NAME? | CE22: =IF(LEFT(VLOOKUP($BV22,TACT!$A$3:$AH$100,7,FALSE),1)="#","-",VLOOKUP($BV22,TACT!$A$3:$AH$100,7,FALSE)) -> #NAME? | CF22: =IF(LEFT(VLOOKUP($BV22,TACT!$A$3:$AH$100,8,FALSE),1)="#","-",VLOOKUP($BV22,TACT!$A$3:$AH$100,8,FALSE)) -> #NAME?
T23: =VLOOKUP($AD23,'市場監控 '!$E$7:$W$194,6,FALSE) -> #NAME? | U23: =VLOOKUP($AD23,'市場監控 '!$E$7:$W$194,7,FALSE) -> #NAME? | V23: =VLOOKUP($AD23,'市場監控 '!$E$7:$W$194,8,FALSE) -> - | W23: =VLOOKUP($AD23,'市場監控 '!$E$7:$W$194,10,FALSE) -> - | X23: =VLOOKUP($AD23,'市場監控 '!$E$7:$W$194,12,FALSE) -> - | Y23: =VLOOKUP($AD23,'市場監控 '!$E$7:$W$194,14,FALSE) -> - | Z23: =VLOOKUP($AD23,'市場監控 '!$E$7:$W$194,15,FALSE) -> - | AA23: =VLOOKUP($AD23,'市場監控 '!$E$7:$W$194,17,FALSE) -> #NAME? | AB23: =VLOOKUP($AD23,'市場監控 '!$E$7:$W$194,18,FALSE) -> #NAME? | AC23: =VLOOKUP($AD23,'市場監控 '!$E$7:$W$194,19,FALSE) -> #NAME? | AD23: CBK GR Equity | AE23: 匯豐控股 | BB23: =VLOOKUP($BD23,NI!$B$5:$AL$2030,6,FALSE) -> #NAME? | BC23: =VLOOKUP($BD23,NI!$B$37:$AL$2030,2,FALSE) -> #NAME? | BD23: =NI!$B81 -> #NAME? | BE23: =VLOOKUP($BD23,NI!$B$5:$AL$2030,11,FALSE) -> #NAME? | BF23: =VLOOKUP($BD23,NI!$B$5:$AL$2030,12,FALSE)/1000000 -> #NAME? | BH23: =IF(ISNUMBER(VLOOKUP($BD23,NI!$B$5:$AL$2030,13,FALSE)),VLOOKUP($BD23,NI!$B$5:$AL$2030,13,FALSE),"-") -> - | BI23: =VLOOKUP($BD23,NI!$B$5:$AL$2030,4,FALSE) -> #NAME? | BJ23: =VLOOKUP($BD23,NI!$B$5:$AL$2030,3,FALSE) -> #NAME? | BK23: =VLOOKUP($BD23,NI!$B$5:$AL$2030,4,FALSE) -> #NAME? | BL23: =IF(LEFT(VLOOKUP($BD23,NI!$B$5:$AL$2030,31,FALSE),1)="#","-",VLOOKUP($BD23,NI!$B$5:$AL$2030,31,FALSE)) -> #NAME? | BM23: =IF(LEFT(VLOOKUP($BD23,NI!$B$5:$AL$2030,32,FALSE),1)="#","-",VLOOKUP($BD23,NI!$B$5:$AL$2030,32,FALSE)) -> #NAME? | BN23: =IF(LEFT(VLOOKUP($BD23,NI!$B$5:$AL$2030,33,FALSE),1)="#","-",VLOOKUP($BD23,NI!$B$5:$AL$2030,33,FALSE)) -> #NAME? | BO23: =VLOOKUP($BD23,NI!$B$5:$AL$2030,22,FALSE) -> #NAME? | BT23: =VLOOKUP($BV23,TACT!$A$3:$AH$100,2,FALSE) -> #NAME? | BU23: =VLOOKUP($BV23,TACT!$A$3:$AH$100,3,FALSE) -> #NAME? | BV23: =TACT!$A18 -> #NAME? | BW23: =VLOOKUP($BV23,TACT!$A$3:$AH$100,11,FALSE) -> #NAME? | BX23: =VLOOKUP($BV23,TACT!$A$3:$AH$100,5,FALSE) -> #NAME? | BZ23: =VLOOKUP($BV23,TACT!$A$3:$AH$100,4,FALSE) -> #NAME? | CA23: =VLOOKUP($BV23,TACT!$A$3:$AH$100,21,FALSE) -> #NAME? | CB23: =VLOOKUP($BV23,TACT!$A$3:$AH$100,32,FALSE) -> #NAME? | CC23: =VLOOKUP($BV23,TACT!$A$3:$AH$100,33,FALSE) -> #NAME? | CD23: =IF(LEFT(VLOOKUP($BV23,TACT!$A$3:$AH$100,6,FALSE),1)="#","-",VLOOKUP($BV23,TACT!$A$3:$AH$100,6,FALSE)) -> #NAME? | CE23: =IF(LEFT(VLOOKUP($BV23,TACT!$A$3:$AH$100,7,FALSE),1)="#","-",VLOOKUP($BV23,TACT!$A$3:$AH$100,7,FALSE)) -> #NAME? | CF23: =IF(LEFT(VLOOKUP($BV23,TACT!$A$3:$AH$100,8,FALSE),1)="#","-",VLOOKUP($BV23,TACT!$A$3:$AH$100,8,FALSE)) -> #NAME?
T24: =VLOOKUP($AD24,'市場監控 '!$E$7:$W$194,6,FALSE) -> #NAME? | U24: =VLOOKUP($AD24,'市場監控 '!$E$7:$W$194,7,FALSE) -> #NAME? | V24: =VLOOKUP($AD24,'市場監控 '!$E$7:$W$194,8,FALSE) -> - | W24: =VLOOKUP($AD24,'市場監控 '!$E$7:$W$194,10,FALSE) -> - | X24: =VLOOKUP($AD24,'市場監控 '!$E$7:$W$194,12,FALSE) -> - | Y24: =VLOOKUP($AD24,'市場監控 '!$E$7:$W$194,14,FALSE) -> - | Z24: =VLOOKUP($AD24,'市場監控 '!$E$7:$W$194,15,FALSE) -> - | AA24: =VLOOKUP($AD24,'市場監控 '!$E$7:$W$194,17,FALSE) -> #NAME? | AB24: =VLOOKUP($AD24,'市場監控 '!$E$7:$W$194,18,FALSE) -> #NAME? | AC24: =VLOOKUP($AD24,'市場監控 '!$E$7:$W$194,19,FALSE) -> #NAME? | AD24: ABN NA Equity | AE24: 渣打集團 | BB24: =VLOOKUP($BD24,NI!$B$5:$AL$2030,6,FALSE) -> #NAME? | BC24: =VLOOKUP($BD24,NI!$B$37:$AL$2030,2,FALSE) -> #NAME? | BD24: =NI!$B82 -> #NAME? | BE24: =VLOOKUP($BD24,NI!$B$5:$AL$2030,11,FALSE) -> #NAME? | BF24: =VLOOKUP($BD24,NI!$B$5:$AL$2030,12,FALSE)/1000000 -> #NAME? | BH24: =IF(ISNUMBER(VLOOKUP($BD24,NI!$B$5:$AL$2030,13,FALSE)),VLOOKUP($BD24,NI!$B$5:$AL$2030,13,FALSE),"-") -> - | BI24: =VLOOKUP($BD24,NI!$B$5:$AL$2030,4,FALSE) -> #NAME? | BJ24: =VLOOKUP($BD24,NI!$B$5:$AL$2030,3,FALSE) -> #NAME? | BK24: =VLOOKUP($BD24,NI!$B$5:$AL$2030,4,FALSE) -> #NAME? | BL24: =IF(LEFT(VLOOKUP($BD24,NI!$B$5:$AL$2030,31,FALSE),1)="#","-",VLOOKUP($BD24,NI!$B$5:$AL$2030,31,FALSE)) -> #NAME? | BM24: =IF(LEFT(VLOOKUP($BD24,NI!$B$5:$AL$2030,32,FALSE),1)="#","-",VLOOKUP($BD24,NI!$B$5:$AL$2030,32,FALSE)) -> #NAME? | BN24: =IF(LEFT(VLOOKUP($BD24,NI!$B$5:$AL$2030,33,FALSE),1)="#","-",VLOOKUP($BD24,NI!$B$5:$AL$2030,33,FALSE)) -> #NAME? | BO24: =VLOOKUP($BD24,NI!$B$5:$AL$2030,22,FALSE) -> #NAME? | BT24: =VLOOKUP($BV24,TACT!$A$3:$AH$100,2,FALSE) -> #NAME? | BU24: =VLOOKUP($BV24,TACT!$A$3:$AH$100,3,FALSE) -> #NAME? | BV24: =TACT!$A19 -> #NAME? | BW24: =VLOOKUP($BV24,TACT!$A$3:$AH$100,11,FALSE) -> #NAME? | BX24: =VLOOKUP($BV24,TACT!$A$3:$AH$100,5,FALSE) -> #NAME? | BZ24: =VLOOKUP($BV24,TACT!$A$3:$AH$100,4,FALSE) -> #NAME? | CA24: =VLOOKUP($BV24,TACT!$A$3:$AH$100,21,FALSE) -> #NAME? | CB24: =VLOOKUP($BV24,TACT!$A$3:$AH$100,32,FALSE) -> #NAME? | CC24: =VLOOKUP($BV24,TACT!$A$3:$AH$100,33,FALSE) -> #NAME? | CD24: =IF(LEFT(VLOOKUP($BV24,TACT!$A$3:$AH$100,6,FALSE),1)="#","-",VLOOKUP($BV24,TACT!$A$3:$AH$100,6,FALSE)) -> #NAME? | CE24: =IF(LEFT(VLOOKUP($BV24,TACT!$A$3:$AH$100,7,FALSE),1)="#","-",VLOOKUP($BV24,TACT!$A$3:$AH$100,7,FALSE)) -> #NAME? | CF24: =IF(LEFT(VLOOKUP($BV24,TACT!$A$3:$AH$100,8,FALSE),1)="#","-",VLOOKUP($BV24,TACT!$A$3:$AH$100,8,FALSE)) -> #NAME? | EN24: 歐洲 | EO24: 7 | EP24: 1 | EQ24: 2 | ER24: 歐盟目標2030年滿足20%內部需求
T25: =VLOOKUP($AD25,'市場監控 '!$E$7:$W$194,6,FALSE) -> #NAME? | U25: =VLOOKUP($AD25,'市場監控 '!$E$7:$W$194,7,FALSE) -> #NAME? | V25: =VLOOKUP($AD25,'市場監控 '!$E$7:$W$194,8,FALSE) -> - | W25: =VLOOKUP($AD25,'市場監控 '!$E$7:$W$194,10,FALSE) -> - | X25: =VLOOKUP($AD25,'市場監控 '!$E$7:$W$194,12,FALSE) -> - | Y25: =VLOOKUP($AD25,'市場監控 '!$E$7:$W$194,14,FALSE) -> - | Z25: =VLOOKUP($AD25,'市場監控 '!$E$7:$W$194,15,FALSE) -> - | AA25: =VLOOKUP($AD25,'市場監控 '!$E$7:$W$194,17,FALSE) -> #NAME? | AB25: =VLOOKUP($AD25,'市場監控 '!$E$7:$W$194,18,FALSE) -> #NAME? | AC25: =VLOOKUP($AD25,'市場監控 '!$E$7:$W$194,19,FALSE) -> #NAME? | AD25: BBVA SM Equity | AE25: 巴克萊集團 | BB25: =VLOOKUP($BD25,NI!$B$5:$AL$2030,6,FALSE) -> #NAME? | BC25: =VLOOKUP($BD25,NI!$B$37:$AL$2030,2,FALSE) -> #NAME? | BD25: =NI!$B83 -> #NAME? | BE25: =VLOOKUP($BD25,NI!$B$5:$AL$2030,11,FALSE) -> #NAME? | BF25: =VLOOKUP($BD25,NI!$B$5:$AL$2030,12,FALSE)/1000000 -> #NAME? | BH25: =IF(ISNUMBER(VLOOKUP($BD25,NI!$B$5:$AL$2030,13,FALSE)),VLOOKUP($BD25,NI!$B$5:$AL$2030,13,FALSE),"-") -> - | BI25: =VLOOKUP($BD25,NI!$B$5:$AL$2030,4,FALSE) -> #NAME? | BJ25: =VLOOKUP($BD25,NI!$B$5:$AL$2030,3,FALSE) -> #NAME? | BK25: =VLOOKUP($BD25,NI!$B$5:$AL$2030,4,FALSE) -> #NAME? | BL25: =IF(LEFT(VLOOKUP($BD25,NI!$B$5:$AL$2030,31,FALSE),1)="#","-",VLOOKUP($BD25,NI!$B$5:$AL$2030,31,FALSE)) -> #NAME? | BM25: =IF(LEFT(VLOOKUP($BD25,NI!$B$5:$AL$2030,32,FALSE),1)="#","-",VLOOKUP($BD25,NI!$B$5:$AL$2030,32,FALSE)) -> #NAME? | BN25: =IF(LEFT(VLOOKUP($BD25,NI!$B$5:$AL$2030,33,FALSE),1)="#","-",VLOOKUP($BD25,NI!$B$5:$AL$2030,33,FALSE)) -> #NAME? | BO25: =VLOOKUP($BD25,NI!$B$5:$AL$2030,22,FALSE) -> #NAME? | BT25: =VLOOKUP($BV25,TACT!$A$3:$AH$100,2,FALSE) -> #NAME? | BU25: =VLOOKUP($BV25,TACT!$A$3:$AH$100,3,FALSE) -> #NAME? | BV25: =TACT!$A20 -> #NAME? | BW25: =VLOOKUP($BV25,TACT!$A$3:$AH$100,11,FALSE) -> #NAME? | BX25: =VLOOKUP($BV25,TACT!$A$3:$AH$100,5,FALSE) -> #NAME? | BZ25: =VLOOKUP($BV25,TACT!$A$3:$AH$100,4,FALSE) -> #NAME? | CA25: =VLOOKUP($BV25,TACT!$A$3:$AH$100,21,FALSE) -> #NAME? | CB25: =VLOOKUP($BV25,TACT!$A$3:$AH$100,32,FALSE) -> #NAME? | CC25: =VLOOKUP($BV25,TACT!$A$3:$AH$100,33,FALSE) -> #NAME? | CD25: =IF(LEFT(VLOOKUP($BV25,TACT!$A$3:$AH$100,6,FALSE),1)="#","-",VLOOKUP($BV25,TACT!$A$3:$AH$100,6,FALSE)) -> #NAME? | CE25: =IF(LEFT(VLOOKUP($BV25,TACT!$A$3:$AH$100,7,FALSE),1)="#","-",VLOOKUP($BV25,TACT!$A$3:$AH$100,7,FALSE)) -> #NAME? | CF25: =IF(LEFT(VLOOKUP($BV25,TACT!$A$3:$AH$100,8,FALSE),1)="#","-",VLOOKUP($BV25,TACT!$A$3:$AH$100,8,FALSE)) -> #NAME? | EX25: IMF與SEC警示私募信貸風險 | EZ25: 2025年10月 | FA25: 1. IMF呼籲監管機構關注銀行對私募信貸基金的風險敞口。 2. SEC要求私募信貸基金提高透明度。 | FD25: 1. 私募信貸機構面臨合規壓力。 2. 投資人對私募信貸資產重新評價，部分基金遭贖回。 3. 信貸市場流動性與定價能力受挑戰。
T26: =VLOOKUP($AD26,'市場監控 '!$E$7:$W$194,6,FALSE) -> #NAME? | U26: =VLOOKUP($AD26,'市場監控 '!$E$7:$W$194,7,FALSE) -> #NAME? | V26: =VLOOKUP($AD26,'市場監控 '!$E$7:$W$194,8,FALSE) -> - | W26: =VLOOKUP($AD26,'市場監控 '!$E$7:$W$194,10,FALSE) -> - | X26: =VLOOKUP($AD26,'市場監控 '!$E$7:$W$194,12,FALSE) -> - | Y26: =VLOOKUP($AD26,'市場監控 '!$E$7:$W$194,14,FALSE) -> - | Z26: =VLOOKUP($AD26,'市場監控 '!$E$7:$W$194,15,FALSE) -> - | AA26: =VLOOKUP($AD26,'市場監控 '!$E$7:$W$194,17,FALSE) -> #NAME? | AB26: =VLOOKUP($AD26,'市場監控 '!$E$7:$W$194,18,FALSE) -> #NAME? | AC26: =VLOOKUP($AD26,'市場監控 '!$E$7:$W$194,19,FALSE) -> #NAME? | AD26: 8316 JP Equity | AE26: 國民西敏寺銀行集團公開有限公司 | BB26: =VLOOKUP($BD26,NI!$B$5:$AL$2030,6,FALSE) -> #NAME? | BC26: =VLOOKUP($BD26,NI!$B$37:$AL$2030,2,FALSE) -> #NAME? | BD26: =NI!$B84 -> #NAME? | BE26: =VLOOKUP($BD26,NI!$B$5:$AL$2030,11,FALSE) -> #NAME? | BF26: =VLOOKUP($BD26,NI!$B$5:$AL$2030,12,FALSE)/1000000 -> #NAME? | BH26: =IF(ISNUMBER(VLOOKUP($BD26,NI!$B$5:$AL$2030,13,FALSE)),VLOOKUP($BD26,NI!$B$5:$AL$2030,13,FALSE),"-") -> - | BI26: =VLOOKUP($BD26,NI!$B$5:$AL$2030,4,FALSE) -> #NAME? | BJ26: =VLOOKUP($BD26,NI!$B$5:$AL$2030,3,FALSE) -> #NAME? | BK26: =VLOOKUP($BD26,NI!$B$5:$AL$2030,4,FALSE) -> #NAME? | BL26: =IF(LEFT(VLOOKUP($BD26,NI!$B$5:$AL$2030,31,FALSE),1)="#","-",VLOOKUP($BD26,NI!$B$5:$AL$2030,31,FALSE)) -> #NAME? | BM26: =IF(LEFT(VLOOKUP($BD26,NI!$B$5:$AL$2030,32,FALSE),1)="#","-",VLOOKUP($BD26,NI!$B$5:$AL$2030,32,FALSE)) -> #NAME? | BN26: =IF(LEFT(VLOOKUP($BD26,NI!$B$5:$AL$2030,33,FALSE),1)="#","-",VLOOKUP($BD26,NI!$B$5:$AL$2030,33,FALSE)) -> #NAME? | BO26: =VLOOKUP($BD26,NI!$B$5:$AL$2030,22,FALSE) -> #NAME? | BT26: =VLOOKUP($BV26,TACT!$A$3:$AH$100,2,FALSE) -> #NAME? | BU26: =VLOOKUP($BV26,TACT!$A$3:$AH$100,3,FALSE) -> #NAME? | BV26: =TACT!$A21 -> #NAME? | BW26: =VLOOKUP($BV26,TACT!$A$3:$AH$100,11,FALSE) -> #NAME? | BX26: =VLOOKUP($BV26,TACT!$A$3:$AH$100,5,FALSE) -> #NAME? | BZ26: =VLOOKUP($BV26,TACT!$A$3:$AH$100,4,FALSE) -> #NAME? | CA26: =VLOOKUP($BV26,TACT!$A$3:$AH$100,21,FALSE) -> #NAME? | CB26: =VLOOKUP($BV26,TACT!$A$3:$AH$100,32,FALSE) -> #NAME? | CC26: =VLOOKUP($BV26,TACT!$A$3:$AH$100,33,FALSE) -> #NAME? | CD26: =IF(LEFT(VLOOKUP($BV26,TACT!$A$3:$AH$100,6,FALSE),1)="#","-",VLOOKUP($BV26,TACT!$A$3:$AH$100,6,FALSE)) -> #NAME? | CE26: =IF(LEFT(VLOOKUP($BV26,TACT!$A$3:$AH$100,7,FALSE),1)="#","-",VLOOKUP($BV26,TACT!$A$3:$AH$100,7,FALSE)) -> #NAME? | CF26: =IF(LEFT(VLOOKUP($BV26,TACT!$A$3:$AH$100,8,FALSE),1)="#","-",VLOOKUP($BV26,TACT!$A$3:$AH$100,8,FALSE)) -> #NAME?
T27: =VLOOKUP($AD27,'市場監控 '!$E$7:$W$194,6,FALSE) -> #NAME? | U27: =VLOOKUP($AD27,'市場監控 '!$E$7:$W$194,7,FALSE) -> #NAME? | V27: =VLOOKUP($AD27,'市場監控 '!$E$7:$W$194,8,FALSE) -> - | W27: =VLOOKUP($AD27,'市場監控 '!$E$7:$W$194,10,FALSE) -> - | X27: =VLOOKUP($AD27,'市場監控 '!$E$7:$W$194,12,FALSE) -> - | Y27: =VLOOKUP($AD27,'市場監控 '!$E$7:$W$194,14,FALSE) -> - | Z27: =VLOOKUP($AD27,'市場監控 '!$E$7:$W$194,15,FALSE) -> - | AA27: =VLOOKUP($AD27,'市場監控 '!$E$7:$W$194,17,FALSE) -> #NAME? | AB27: =VLOOKUP($AD27,'市場監控 '!$E$7:$W$194,18,FALSE) -> #NAME? | AC27: =VLOOKUP($AD27,'市場監控 '!$E$7:$W$194,19,FALSE) -> #NAME? | AD27: 8411 JP Equity | AE27: 駿懋銀行集團 | BB27: =VLOOKUP($BD27,NI!$B$5:$AL$2030,6,FALSE) -> #NAME? | BC27: =VLOOKUP($BD27,NI!$B$37:$AL$2030,2,FALSE) -> #NAME? | BD27: =NI!$B85 -> #NAME? | BE27: =VLOOKUP($BD27,NI!$B$5:$AL$2030,11,FALSE) -> #NAME? | BF27: =VLOOKUP($BD27,NI!$B$5:$AL$2030,12,FALSE)/1000000 -> #NAME? | BH27: =IF(ISNUMBER(VLOOKUP($BD27,NI!$B$5:$AL$2030,13,FALSE)),VLOOKUP($BD27,NI!$B$5:$AL$2030,13,FALSE),"-") -> - | BI27: =VLOOKUP($BD27,NI!$B$5:$AL$2030,4,FALSE) -> #NAME? | BJ27: =VLOOKUP($BD27,NI!$B$5:$AL$2030,3,FALSE) -> #NAME? | BK27: =VLOOKUP($BD27,NI!$B$5:$AL$2030,4,FALSE) -> #NAME? | BL27: =IF(LEFT(VLOOKUP($BD27,NI!$B$5:$AL$2030,31,FALSE),1)="#","-",VLOOKUP($BD27,NI!$B$5:$AL$2030,31,FALSE)) -> #NAME? | BM27: =IF(LEFT(VLOOKUP($BD27,NI!$B$5:$AL$2030,32,FALSE),1)="#","-",VLOOKUP($BD27,NI!$B$5:$AL$2030,32,FALSE)) -> #NAME? | BN27: =IF(LEFT(VLOOKUP($BD27,NI!$B$5:$AL$2030,33,FALSE),1)="#","-",VLOOKUP($BD27,NI!$B$5:$AL$2030,33,FALSE)) -> #NAME? | BO27: =VLOOKUP($BD27,NI!$B$5:$AL$2030,22,FALSE) -> #NAME? | BT27: =VLOOKUP($BV27,TACT!$A$3:$AH$100,2,FALSE) -> #NAME? | BU27: =VLOOKUP($BV27,TACT!$A$3:$AH$100,3,FALSE) -> #NAME? | BV27: =TACT!$A22 -> #NAME? | BW27: =VLOOKUP($BV27,TACT!$A$3:$AH$100,11,FALSE) -> #NAME? | BX27: =VLOOKUP($BV27,TACT!$A$3:$AH$100,5,FALSE) -> #NAME? | BZ27: =VLOOKUP($BV27,TACT!$A$3:$AH$100,4,FALSE) -> #NAME? | CA27: =VLOOKUP($BV27,TACT!$A$3:$AH$100,21,FALSE) -> #NAME? | CB27: =VLOOKUP($BV27,TACT!$A$3:$AH$100,32,FALSE) -> #NAME? | CC27: =VLOOKUP($BV27,TACT!$A$3:$AH$100,33,FALSE) -> #NAME? | CD27: =IF(LEFT(VLOOKUP($BV27,TACT!$A$3:$AH$100,6,FALSE),1)="#","-",VLOOKUP($BV27,TACT!$A$3:$AH$100,6,FALSE)) -> #NAME? | CE27: =IF(LEFT(VLOOKUP($BV27,TACT!$A$3:$AH$100,7,FALSE),1)="#","-",VLOOKUP($BV27,TACT!$A$3:$AH$100,7,FALSE)) -> #NAME? | CF27: =IF(LEFT(VLOOKUP($BV27,TACT!$A$3:$AH$100,8,FALSE),1)="#","-",VLOOKUP($BV27,TACT!$A$3:$AH$100,8,FALSE)) -> #NAME?
T28: =VLOOKUP($AD28,'市場監控 '!$E$7:$W$194,6,FALSE) -> #NAME? | U28: =VLOOKUP($AD28,'市場監控 '!$E$7:$W$194,7,FALSE) -> #NAME? | V28: =VLOOKUP($AD28,'市場監控 '!$E$7:$W$194,8,FALSE) -> - | W28: =VLOOKUP($AD28,'市場監控 '!$E$7:$W$194,10,FALSE) -> - | X28: =VLOOKUP($AD28,'市場監控 '!$E$7:$W$194,12,FALSE) -> - | Y28: =VLOOKUP($AD28,'市場監控 '!$E$7:$W$194,14,FALSE) -> - | Z28: =VLOOKUP($AD28,'市場監控 '!$E$7:$W$194,15,FALSE) -> - | AA28: =VLOOKUP($AD28,'市場監控 '!$E$7:$W$194,17,FALSE) -> #NAME? | AB28: =VLOOKUP($AD28,'市場監控 '!$E$7:$W$194,18,FALSE) -> #NAME? | AC28: =VLOOKUP($AD28,'市場監控 '!$E$7:$W$194,19,FALSE) -> #NAME? | AD28: 3328 HK Equity | AE28: 德意志銀行 | BB28: =VLOOKUP($BD28,NI!$B$5:$AL$2030,6,FALSE) -> #NAME? | BC28: =VLOOKUP($BD28,NI!$B$37:$AL$2030,2,FALSE) -> #NAME? | BD28: =NI!$B86 -> #NAME? | BE28: =VLOOKUP($BD28,NI!$B$5:$AL$2030,11,FALSE) -> #NAME? | BF28: =VLOOKUP($BD28,NI!$B$5:$AL$2030,12,FALSE)/1000000 -> #NAME? | BH28: =IF(ISNUMBER(VLOOKUP($BD28,NI!$B$5:$AL$2030,13,FALSE)),VLOOKUP($BD28,NI!$B$5:$AL$2030,13,FALSE),"-") -> - | BI28: =VLOOKUP($BD28,NI!$B$5:$AL$2030,4,FALSE) -> #NAME? | BJ28: =VLOOKUP($BD28,NI!$B$5:$AL$2030,3,FALSE) -> #NAME? | BK28: =VLOOKUP($BD28,NI!$B$5:$AL$2030,4,FALSE) -> #NAME? | BL28: =IF(LEFT(VLOOKUP($BD28,NI!$B$5:$AL$2030,31,FALSE),1)="#","-",VLOOKUP($BD28,NI!$B$5:$AL$2030,31,FALSE)) -> #NAME? | BM28: =IF(LEFT(VLOOKUP($BD28,NI!$B$5:$AL$2030,32,FALSE),1)="#","-",VLOOKUP($BD28,NI!$B$5:$AL$2030,32,FALSE)) -> #NAME? | BN28: =IF(LEFT(VLOOKUP($BD28,NI!$B$5:$AL$2030,33,FALSE),1)="#","-",VLOOKUP($BD28,NI!$B$5:$AL$2030,33,FALSE)) -> #NAME? | BO28: =VLOOKUP($BD28,NI!$B$5:$AL$2030,22,FALSE) -> #NAME?
